Workbook

Sheet Konfigurasi Model
A1: Single Layer Perceptron — Klasifikasi Iris Setosa vs Iris Versicolor
A3: Arsitektur & Hyperparameter
A4: Parameter | B4: Nilai | C4: Keterangan
A5: Jumlah neuron input (X1–X4) | B5: 4 | C5: SepalLength, SepalWidth, PetalLength, PetalWidth
A6: Jumlah neuron output | B6: 1 | C6: Binary encoding, 1 neuron
A7: Target — Iris Setosa | B7: 0 | C7: Kelas negatif
A8: Target — Iris Versicolor | B8: 1 | C8: Kelas positif
A9: Bobot awal teta1–teta4 | B9: 0.5 | C9: Nilai inisiasi dari template PMM
A10: Bias awal | B10: 0.5 | C10: Nilai inisiasi dari template PMM
A11: Learning Rate | B11: 0.1 | C11: Nilai inisiasi dari template PMM
A12: Sigmoid | B12: g(z) = 1/(1+e^(−z)) | C12: z = bias + teta1·X1 + teta2·X2 + teta3·X3 + teta4·X4
A13: error | B13: g(z) − TARGET | C13: Selisih output sigmoid dengan target
A14: Sum Square Error | B14: error² | C14: Dirata-rata jadi MSE per epoch
A15: Metode update | B15: Gradient Descent (stochastic, per data) | C15: teta = teta − LR·dteta ; bias = bias − LR·dbias
A16: Jumlah epoch | B16: 5 | C16: Bobot baris terakhir tiap epoch = bobot awal epoch berikutnya
A17: Jumlah data training | B17: 80 | C17: 40 Setosa + 40 Versicolor
A18: Jumlah data testing | B18: 20 | C18: 10 Setosa + 10 Versicolor
A19: Urutan data training | B19: Selang-seling blok 20 (0–1–0–1) | C19: Versi tanpa acak ada di sheet Trial
A20: Threshold prediksi | B20: 0.5 | C20: g(z) > 0.5 → 1, selainnya → 0
A21: Bobot untuk testing | B21: Sama dengan baris training terakhir | C21: Tidak ada update tambahan setelah data ke-80
A24: Rumus turunan (slide SLP – Gradient Descent)
A25: dteta_j = 2·[g(z) − TARGET]·[1 − g(z)]·g(z)·X_j
A26: dbias = 2·[g(z) − TARGET]·[1 − g(z)]·g(z)
A27: teta_j ← teta_j − LR·dteta_j bias ← bias − LR·dbias

Sheet Epoch 1
A1: EPOCH 1 — TRAINING (80 data)
G2: Setosa = 0 | I2: Learning Rate | K2: ='Konfigurasi Model'!$B$11 -> 0.1
G3: Versicolor = 1 | I3: Bobot bias | N3: dot | O3: Sigmoid | P3: Prediksi | Q3: error | R3: Sum Square Error
A4: EPOCH | B4: No | C4: X1 | D4: X2 | E4: X3 | F4: X4 | G4: TARGET | I4: bias | J4: teta1 | K4: teta2 | L4: teta 3 | M4: teta4 | N4: z | O4: g(z) | T4: dbias | U4: dteta1 | V4: dteta2 | W4: dteta3 | X4: dteta4 | Y4: Akurasi
A5: epoch 1 | B5: 1 | C5: 5.1 | D5: 3.5 | E5: 1.4 | F5: 0.2 | G5: 0 | I5: ='Konfigurasi Model'!$B$10 -> 0.5 | J5: ='Konfigurasi Model'!$B$9 -> 0.5 | K5: ='Konfigurasi Model'!$B$9 -> 0.5 | L5: ='Konfigurasi Model'!$B$9 -> 0.5 | M5: ='Konfigurasi Model'!$B$9 -> 0.5 | N5: =I5+J5*C5+K5*D5+L5*E5+M5*F5 -> 5.6 | O5: =1/(1+EXP(-N5)) -> 0.99631576 | P5: =IF(O5>0.5,1,0) -> 1 | Q5: =O5-G5 -> 0.99631576 | R5: =Q5^2 -> 0.99264509 | T5: =2*(O5-G5)*(1-O5)*O5 -> 0.0073142853 | U5: =2*(O5-G5)*(1-O5)*O5*C5 -> 0.037302855 | V5: =2*(O5-G5)*(1-O5)*O5*D5 -> 0.025599999 | W5: =2*(O5-G5)*(1-O5)*O5*E5 -> 0.010239999 | X5: =2*(O5-G5)*(1-O5)*O5*F5 -> 0.0014628571 | Y5: =IF(P5=G5,1,0) -> 0
B6: 2 | C6: 4.9 | D6: 3 | E6: 1.4 | F6: 0.2 | G6: 0 | I6: =I5-('Konfigurasi Model'!$B$11*T5) -> 0.49926857 | J6: =J5-('Konfigurasi Model'!$B$11*U5) -> 0.49626971 | K6: =K5-('Konfigurasi Model'!$B$11*V5) -> 0.49744 | L6: =L5-('Konfigurasi Model'!$B$11*W5) -> 0.498976 | M6: =M5-('Konfigurasi Model'!$B$11*X5) -> 0.49985371 | N6: =I6+J6*C6+K6*D6+L6*E6+M6*F6 -> 5.2218473 | O6: =1/(1+EXP(-N6)) -> 0.99463163 | P6: =IF(O6>0.5,1,0) -> 1 | Q6: =O6-G6 -> 0.99463163 | R6: =Q6^2 -> 0.98929207 | T6: =2*(O6-G6)*(1-O6)*O6 -> 0.01062178 | U6: =2*(O6-G6)*(1-O6)*O6*C6 -> 0.052046723 | V6: =2*(O6-G6)*(1-O6)*O6*D6 -> 0.031865341 | W6: =2*(O6-G6)*(1-O6)*O6*E6 -> 0.014870492 | X6: =2*(O6-G6)*(1-O6)*O6*F6 -> 0.0021243561 | Y6: =IF(P6=G6,1,0) -> 0
B7: 3 | C7: 4.7 | D7: 3.2 | E7: 1.3 | F7: 0.2 | G7: 0 | I7: =I6-('Konfigurasi Model'!$B$11*T6) -> 0.49820639 | J7: =J6-('Konfigurasi Model'!$B$11*U6) -> 0.49106504 | K7: =K6-('Konfigurasi Model'!$B$11*V6) -> 0.49425347 | L7: =L6-('Konfigurasi Model'!$B$11*W6) -> 0.49748895 | M7: =M6-('Konfigurasi Model'!$B$11*X6) -> 0.49964128 | N7: =I7+J7*C7+K7*D7+L7*E7+M7*F7 -> 5.1344871 | O7: =1/(1+EXP(-N7)) -> 0.99414442 | P7: =IF(O7>0.5,1,0) -> 1 | Q7: =O7-G7 -> 0.99414442 | R7: =Q7^2 -> 0.98832312 | T7: =2*(O7-G7)*(1-O7)*O7 -> 0.011574414 | U7: =2*(O7-G7)*(1-O7)*O7*C7 -> 0.054399748 | V7: =2*(O7-G7)*(1-O7)*O7*D7 -> 0.037038126 | W7: =2*(O7-G7)*(1-O7)*O7*E7 -> 0.015046739 | X7: =2*(O7-G7)*(1-O7)*O7*F7 -> 0.0023148829 | Y7: =IF(P7=G7,1,0) -> 0
B8: 4 | C8: 4.6 | D8: 3.1 | E8: 1.5 | F8: 0.2 | G8: 0 | I8: =I7-('Konfigurasi Model'!$B$11*T7) -> 0.49704895 | J8: =J7-('Konfigurasi Model'!$B$11*U7) -> 0.48562507 | K8: =K7-('Konfigurasi Model'!$B$11*V7) -> 0.49054965 | L8: =L7-('Konfigurasi Model'!$B$11*W7) -> 0.49598428 | M8: =M7-('Konfigurasi Model'!$B$11*X7) -> 0.49940979 | N8: =I8+J8*C8+K8*D8+L8*E8+M8*F8 -> 5.0954866 | O8: =1/(1+EXP(-N8)) -> 0.99391295 | P8: =IF(O8>0.5,1,0) -> 1 | Q8: =O8-G8 -> 0.99391295 | R8: =Q8^2 -> 0.98786296 | T8: =2*(O8-G8)*(1-O8)*O8 -> 0.012026336 | U8: =2*(O8-G8)*(1-O8)*O8*C8 -> 0.055321148 | V8: =2*(O8-G8)*(1-O8)*O8*D8 -> 0.037281643 | W8: =2*(O8-G8)*(1-O8)*O8*E8 -> 0.018039505 | X8: =2*(O8-G8)*(1-O8)*O8*F8 -> 0.0024052673 | Y8: =IF(P8=G8,1,0) -> 0
B9: 5 | C9: 5 | D9: 3.6 | E9: 1.4 | F9: 0.2 | G9: 0 | I9: =I8-('Konfigurasi Model'!$B$11*T8) -> 0.49584632 | J9: =J8-('Konfigurasi Model'!$B$11*U8) -> 0.48009295 | K9: =K8-('Konfigurasi Model'!$B$11*V8) -> 0.48682149 | L9: =L8-('Konfigurasi Model'!$B$11*W8) -> 0.49418033 | M9: =M8-('Konfigurasi Model'!$B$11*X8) -> 0.49916926 | N9: =I9+J9*C9+K9*D9+L9*E9+M9*F9 -> 5.4405548 | O9: =1/(1+EXP(-N9)) -> 0.99568165 | P9: =IF(O9>0.5,1,0) -> 1 | Q9: =O9-G9 -> 0.99568165 | R9: =Q9^2 -> 0.99138195 | T9: =2*(O9-G9)*(1-O9)*O9 -> 0.0085622637 | U9: =2*(O9-G9)*(1-O9)*O9*C9 -> 0.042811319 | V9: =2*(O9-G9)*(1-O9)*O9*D9 -> 0.030824149 | W9: =2*(O9-G9)*(1-O9)*O9*E9 -> 0.011987169 | X9: =2*(O9-G9)*(1-O9)*O9*F9 -> 0.0017124527 | Y9: =IF(P9=G9,1,0) -> 0
B10: 6 | C10: 5.4 | D10: 3.9 | E10: 1.7 | F10: 0.4 | G10: 0 | I10: =I9-('Konfigurasi Model'!$B$11*T9) -> 0.49499009 | J10: =J9-('Konfigurasi Model'!$B$11*U9) -> 0.47581182 | K10: =K9-('Konfigurasi Model'!$B$11*V9) -> 0.48373907 | L10: =L9-('Konfigurasi Model'!$B$11*W9) -> 0.49298161 | M10: =M9-('Konfigurasi Model'!$B$11*X9) -> 0.49899802 | N10: =I10+J10*C10+K10*D10+L10*E10+M10*F10 -> 5.9886243 | O10: =1/(1+EXP(-N10)) -> 0.99749916 | P10: =IF(O10>0.5,1,0) -> 1 | Q10: =O10-G10 -> 0.99749916 | R10: =Q10^2 -> 0.99500457 | T10: =2*(O10-G10)*(1-O10)*O10 -> 0.0049766963 | U10: =2*(O10-G10)*(1-O10)*O10*C10 -> 0.02687416 | V10: =2*(O10-G10)*(1-O10)*O10*D10 -> 0.019409116 | W10: =2*(O10-G10)*(1-O10)*O10*E10 -> 0.0084603838 | X10: =2*(O10-G10)*(1-O10)*O10*F10 -> 0.0019906785 | Y10: =IF(P10=G10,1,0) -> 0
B11: 7 | C11: 4.6 | D11: 3.4 | E11: 1.4 | F11: 0.3 | G11: 0 | I11: =I10-('Konfigurasi Model'!$B$11*T10) -> 0.49449242 | J11: =J10-('Konfigurasi Model'!$B$11*U10) -> 0.4731244 | K11: =K10-('Konfigurasi Model'!$B$11*V10) -> 0.48179816 | L11: =L10-('Konfigurasi Model'!$B$11*W10) -> 0.49213557 | M11: =M10-('Konfigurasi Model'!$B$11*X10) -> 0.49879895 | N11: =I11+J11*C11+K11*D11+L11*E11+M11*F11 -> 5.1476079 | O11: =1/(1+EXP(-N11)) -> 0.99422031 | P11: =IF(O11>0.5,1,0) -> 1 | Q11: =O11-G11 -> 0.99422031 | R11: =Q11^2 -> 0.98847402 | T11: =2*(O11-G11)*(1-O11)*O11 -> 0.011426156 | U11: =2*(O11-G11)*(1-O11)*O11*C11 -> 0.05256032 | V11: =2*(O11-G11)*(1-O11)*O11*D11 -> 0.038848932 | W11: =2*(O11-G11)*(1-O11)*O11*E11 -> 0.015996619 | X11: =2*(O11-G11)*(1-O11)*O11*F11 -> 0.0034278469 | Y11: =IF(P11=G11,1,0) -> 0
B12: 8 | C12: 5 | D12: 3.4 | E12: 1.5 | F12: 0.2 | G12: 0 | I12: =I11-('Konfigurasi Model'!$B$11*T11) -> 0.49334981 | J12: =J11-('Konfigurasi Model'!$B$11*U11) -> 0.46786837 | K12: =K11-('Konfigurasi Model'!$B$11*V11) -> 0.47791327 | L12: =L11-('Konfigurasi Model'!$B$11*W11) -> 0.49053591 | M12: =M11-('Konfigurasi Model'!$B$11*X11) -> 0.49845617 | N12: =I12+J12*C12+K12*D12+L12*E12+M12*F12 -> 5.2930919 | O12: =1/(1+EXP(-N12)) -> 0.99499894 | P12: =IF(O12>0.5,1,0) -> 1 | Q12: =O12-G12 -> 0.99499894 | R12: =Q12^2 -> 0.99002289 | T12: =2*(O12-G12)*(1-O12)*O12 -> 0.0099023268 | U12: =2*(O12-G12)*(1-O12)*O12*C12 -> 0.049511634 | V12: =2*(O12-G12)*(1-O12)*O12*D12 -> 0.033667911 | W12: =2*(O12-G12)*(1-O12)*O12*E12 -> 0.01485349 | X12: =2*(O12-G12)*(1-O12)*O12*F12 -> 0.0019804654 | Y12: =IF(P12=G12,1,0) -> 0
B13: 9 | C13: 4.4 | D13: 2.9 | E13: 1.4 | F13: 0.2 | G13: 0 | I13: =I12-('Konfigurasi Model'!$B$11*T12) -> 0.49235957 | J13: =J12-('Konfigurasi Model'!$B$11*U12) -> 0.46291721 | K13: =K12-('Konfigurasi Model'!$B$11*V12) -> 0.47454648 | L13: =L12-('Konfigurasi Model'!$B$11*W12) -> 0.48905056 | M13: =M12-('Konfigurasi Model'!$B$11*X12) -> 0.49825812 | N13: =I13+J13*C13+K13*D13+L13*E13+M13*F13 -> 4.6897025 | O13: =1/(1+EXP(-N13)) -> 0.99089426 | P13: =IF(O13>0.5,1,0) -> 1 | Q13: =O13-G13 -> 0.99089426 | R13: =Q13^2 -> 0.98187143 | T13: =2*(O13-G13)*(1-O13)*O13 -> 0.017881338 | U13: =2*(O13-G13)*(1-O13)*O13*C13 -> 0.078677888 | V13: =2*(O13-G13)*(1-O13)*O13*D13 -> 0.051855881 | W13: =2*(O13-G13)*(1-O13)*O13*E13 -> 0.025033873 | X13: =2*(O13-G13)*(1-O13)*O13*F13 -> 0.0035762676 | Y13: =IF(P13=G13,1,0) -> 0
B14: 10 | C14: 4.9 | D14: 3.1 | E14: 1.5 | F14: 0.1 | G14: 0 | I14: =I13-('Konfigurasi Model'!$B$11*T13) -> 0.49057144 | J14: =J13-('Konfigurasi Model'!$B$11*U13) -> 0.45504942 | K14: =K13-('Konfigurasi Model'!$B$11*V13) -> 0.46936089 | L14: =L13-('Konfigurasi Model'!$B$11*W13) -> 0.48654717 | M14: =M13-('Konfigurasi Model'!$B$11*X13) -> 0.49790049 | N14: =I14+J14*C14+K14*D14+L14*E14+M14*F14 -> 4.9549432 | O14: =1/(1+EXP(-N14)) -> 0.99300085 | P14: =IF(O14>0.5,1,0) -> 1 | Q14: =O14-G14 -> 0.99300085 | R14: =Q14^2 -> 0.98605069 | T14: =2*(O14-G14)*(1-O14)*O14 -> 0.013803028 | U14: =2*(O14-G14)*(1-O14)*O14*C14 -> 0.067634839 | V14: =2*(O14-G14)*(1-O14)*O14*D14 -> 0.042789388 | W14: =2*(O14-G14)*(1-O14)*O14*E14 -> 0.020704543 | X14: =2*(O14-G14)*(1-O14)*O14*F14 -> 0.0013803028 | Y14: =IF(P14=G14,1,0) -> 0
B15: 11 | C15: 5.4 | D15: 3.7 | E15: 1.5 | F15: 0.2 | G15: 0 | I15: =I14-('Konfigurasi Model'!$B$11*T14) -> 0.48919114 | J15: =J14-('Konfigurasi Model'!$B$11*U14) -> 0.44828594 | K15: =K14-('Konfigurasi Model'!$B$11*V14) -> 0.46508195 | L15: =L14-('Konfigurasi Model'!$B$11*W14) -> 0.48447672 | M15: =M14-('Konfigurasi Model'!$B$11*X14) -> 0.49776246 | N15: =I15+J15*C15+K15*D15+L15*E15+M15*F15 -> 5.457006 | O15: =1/(1+EXP(-N15)) -> 0.99575181 | P15: =IF(O15>0.5,1,0) -> 1 | Q15: =O15-G15 -> 0.99575181 | R15: =Q15^2 -> 0.99152168 | T15: =2*(O15-G15)*(1-O15)*O15 -> 0.0084243369 | U15: =2*(O15-G15)*(1-O15)*O15*C15 -> 0.045491419 | V15: =2*(O15-G15)*(1-O15)*O15*D15 -> 0.031170047 | W15: =2*(O15-G15)*(1-O15)*O15*E15 -> 0.012636505 | X15: =2*(O15-G15)*(1-O15)*O15*F15 -> 0.0016848674 | Y15: =IF(P15=G15,1,0) -> 0
B16: 12 | C16: 4.8 | D16: 3.4 | E16: 1.6 | F16: 0.2 | G16: 0 | I16: =I15-('Konfigurasi Model'!$B$11*T15) -> 0.4883487 | J16: =J15-('Konfigurasi Model'!$B$11*U15) -> 0.44373679 | K16: =K15-('Konfigurasi Model'!$B$11*V15) -> 0.46196495 | L16: =L15-('Konfigurasi Model'!$B$11*W15) -> 0.48321307 | M16: =M15-('Konfigurasi Model'!$B$11*X15) -> 0.49759398 | N16: =I16+J16*C16+K16*D16+L16*E16+M16*F16 -> 5.0616258 | O16: =1/(1+EXP(-N16)) -> 0.99370463 | P16: =IF(O16>0.5,1,0) -> 1 | Q16: =O16-G16 -> 0.99370463 | R16: =Q16^2 -> 0.9874489 | T16: =2*(O16-G16)*(1-O16)*O16 -> 0.012432709 | U16: =2*(O16-G16)*(1-O16)*O16*C16 -> 0.059677003 | V16: =2*(O16-G16)*(1-O16)*O16*D16 -> 0.04227121 | W16: =2*(O16-G16)*(1-O16)*O16*E16 -> 0.019892334 | X16: =2*(O16-G16)*(1-O16)*O16*F16 -> 0.0024865418 | Y16: =IF(P16=G16,1,0) -> 0
B17: 13 | C17: 4.8 | D17: 3 | E17: 1.4 | F17: 0.1 | G17: 0 | I17: =I16-('Konfigurasi Model'!$B$11*T16) -> 0.48710543 | J17: =J16-('Konfigurasi Model'!$B$11*U16) -> 0.43776909 | K17: =K16-('Konfigurasi Model'!$B$11*V16) -> 0.45773783 | L17: =L16-('Konfigurasi Model'!$B$11*W16) -> 0.48122383 | M17: =M16-('Konfigurasi Model'!$B$11*X16) -> 0.49734532 | N17: =I17+J17*C17+K17*D17+L17*E17+M17*F17 -> 4.6850585 | O17: =1/(1+EXP(-N17)) -> 0.99085226 | P17: =IF(O17>0.5,1,0) -> 1 | Q17: =O17-G17 -> 0.99085226 | R17: =Q17^2 -> 0.9817882 | T17: =2*(O17-G17)*(1-O17)*O17 -> 0.017962289 | U17: =2*(O17-G17)*(1-O17)*O17*C17 -> 0.086218985 | V17: =2*(O17-G17)*(1-O17)*O17*D17 -> 0.053886866 | W17: =2*(O17-G17)*(1-O17)*O17*E17 -> 0.025147204 | X17: =2*(O17-G17)*(1-O17)*O17*F17 -> 0.0017962289 | Y17: =IF(P17=G17,1,0) -> 0
... B84: 80 | C84: 5.5 | D84: 2.5 | E84: 4 | F84: 1.3 | G84: 1 | I84: =I83-('Konfigurasi Model'!$B$11*T83) -> 0.37596004 | J84: =J83-('Konfigurasi Model'!$B$11*U83) -> -0.071457626 | K84: =K83-('Konfigurasi Model'!$B$11*V83) -> 0.059374095 | L84: =L83-('Konfigurasi Model'!$B$11*W83) -> 0.50900842 | M84: =M83-('Konfigurasi Model'!$B$11*X83) -> 0.55599671 | N84: =I84+J84*C84+K84*D84+L84*E84+M84*F84 -> 2.8902077 | O84: =1/(1+EXP(-N84)) -> 0.94736024 | P84: =IF(O84>0.5,1,0) -> 1 | Q84: =O84-G84 -> -0.052639758 | R84: =Q84^2 -> 0.0027709442 | T84: =2*(O84-G84)*(1-O84)*O84 -> -0.0052501647 | U84: =2*(O84-G84)*(1-O84)*O84*C84 -> -0.028875906 | V84: =2*(O84-G84)*(1-O84)*O84*D84 -> -0.013125412 | W84: =2*(O84-G84)*(1-O84)*O84*E84 -> -0.021000659 | X84: =2*(O84-G84)*(1-O84)*O84*F84 -> -0.0068252141 | Y84: =IF(P84=G84,1,0) -> 1
Q85: MSE → | R85: =AVERAGE(R5:R84) -> 0.44715463 | X85: Akurasi → | Y85: =AVERAGE(Y5:Y84) -> 0.525
A87: EPOCH 1 — TESTING (20 data, bobot = baris 84)
G88: Setosa = 0 | I88: Learning Rate | K88: ='Konfigurasi Model'!$B$11 -> 0.1
G89: Versicolor = 1 | I89: Bobot bias | N89: dot | O89: Sigmoid | P89: Prediksi | Q89: error | R89: Sum Square Error
A90: EPOCH | B90: No | C90: X1 | D90: X2 | E90: X3 | F90: X4 | G90: TARGET | I90: bias | J90: teta1 | K90: teta2 | L90: teta 3 | M90: teta4 | N90: z | O90: g(z) | T90: Akurasi
A91: testing | B91: 1 | C91: 5 | D91: 3.5 | E91: 1.3 | F91: 0.3 | G91: 0 | I91: =I84 -> 0.37596004 | J91: =J84 -> -0.071457626 | K91: =K84 -> 0.059374095 | L91: =L84 -> 0.50900842 | M91: =M84 -> 0.55599671 | N91: =I91+J91*C91+K91*D91+L91*E91+M91*F91 -> 1.0549912 | O91: =1/(1+EXP(-N91)) -> 0.74173219 | P91: =IF(O91>0.5,1,0) -> 1 | Q91: =O91-G91 -> 0.74173219 | R91: =Q91^2 -> 0.55016665 | T91: =IF(P91=G91,1,0) -> 0
B92: 2 | C92: 4.5 | D92: 2.3 | E92: 1.3 | F92: 0.3 | G92: 0 | I92: =I91 -> 0.37596004 | J92: =J91 -> -0.071457626 | K92: =K91 -> 0.059374095 | L92: =L91 -> 0.50900842 | M92: =M91 -> 0.55599671 | N92: =I92+J92*C92+K92*D92+L92*E92+M92*F92 -> 1.0194711 | O92: =1/(1+EXP(-N92)) -> 0.73486956 | P92: =IF(O92>0.5,1,0) -> 1 | Q92: =O92-G92 -> 0.73486956 | R92: =Q92^2 -> 0.54003327 | T92: =IF(P92=G92,1,0) -> 0
B93: 3 | C93: 4.4 | D93: 3.2 | E93: 1.3 | F93: 0.2 | G93: 0 | I93: =I92 -> 0.37596004 | J93: =J92 -> -0.071457626 | K93: =K92 -> 0.059374095 | L93: =L92 -> 0.50900842 | M93: =M92 -> 0.55599671 | N93: =I93+J93*C93+K93*D93+L93*E93+M93*F93 -> 1.0244539 | O93: =1/(1+EXP(-N93)) -> 0.73583925 | P93: =IF(O93>0.5,1,0) -> 1 | Q93: =O93-G93 -> 0.73583925 | R93: =Q93^2 -> 0.5414594 | T93: =IF(P93=G93,1,0) -> 0
B94: 4 | C94: 5 | D94: 3.5 | E94: 1.6 | F94: 0.6 | G94: 0 | I94: =I93 -> 0.37596004 | J94: =J93 -> -0.071457626 | K94: =K93 -> 0.059374095 | L94: =L93 -> 0.50900842 | M94: =M93 -> 0.55599671 | N94: =I94+J94*C94+K94*D94+L94*E94+M94*F94 -> 1.3744927 | O94: =1/(1+EXP(-N94)) -> 0.79810505 | P94: =IF(O94>0.5,1,0) -> 1 | Q94: =O94-G94 -> 0.79810505 | R94: =Q94^2 -> 0.63697168 | T94: =IF(P94=G94,1,0) -> 0
B95: 5 | C95: 5.1 | D95: 3.8 | E95: 1.9 | F95: 0.4 | G95: 0 | I95: =I94 -> 0.37596004 | J95: =J94 -> -0.071457626 | K95: =K94 -> 0.059374095 | L95: =L94 -> 0.50900842 | M95: =M94 -> 0.55599671 | N95: =I95+J95*C95+K95*D95+L95*E95+M95*F95 -> 1.4266624 | O95: =1/(1+EXP(-N95)) -> 0.80638074 | P95: =IF(O95>0.5,1,0) -> 1 | Q95: =O95-G95 -> 0.80638074 | R95: =Q95^2 -> 0.6502499 | T95: =IF(P95=G95,1,0) -> 0
B96: 6 | C96: 4.8 | D96: 3 | E96: 1.4 | F96: 0.3 | G96: 0 | I96: =I95 -> 0.37596004 | J96: =J95 -> -0.071457626 | K96: =K95 -> 0.059374095 | L96: =L95 -> 0.50900842 | M96: =M95 -> 0.55599671 | N96: =I96+J96*C96+K96*D96+L96*E96+M96*F96 -> 1.0904965 | O96: =1/(1+EXP(-N96)) -> 0.74847521 | P96: =IF(O96>0.5,1,0) -> 1 | Q96: =O96-G96 -> 0.74847521 | R96: =Q96^2 -> 0.56021514 | T96: =IF(P96=G96,1,0) -> 0
B97: 7 | C97: 5.1 | D97: 3.8 | E97: 1.6 | F97: 0.2 | G97: 0 | I97: =I96 -> 0.37596004 | J97: =J96 -> -0.071457626 | K97: =K96 -> 0.059374095 | L97: =L96 -> 0.50900842 | M97: =M96 -> 0.55599671 | N97: =I97+J97*C97+K97*D97+L97*E97+M97*F97 -> 1.1627605 | O97: =1/(1+EXP(-N97)) -> 0.76183395 | P97: =IF(O97>0.5,1,0) -> 1 | Q97: =O97-G97 -> 0.76183395 | R97: =Q97^2 -> 0.58039097 | T97: =IF(P97=G97,1,0) -> 0
B98: 8 | C98: 4.6 | D98: 3.2 | E98: 1.4 | F98: 0.2 | G98: 0 | I98: =I97 -> 0.37596004 | J98: =J97 -> -0.071457626 | K98: =K97 -> 0.059374095 | L98: =L97 -> 0.50900842 | M98: =M97 -> 0.55599671 | N98: =I98+J98*C98+K98*D98+L98*E98+M98*F98 -> 1.0610632 | O98: =1/(1+EXP(-N98)) -> 0.74289367 | P98: =IF(O98>0.5,1,0) -> 1 | Q98: =O98-G98 -> 0.74289367 | R98: =Q98^2 -> 0.551891 | T98: =IF(P98=G98,1,0) -> 0
B99: 9 | C99: 5.3 | D99: 3.7 | E99: 1.5 | F99: 0.2 | G99: 0 | I99: =I98 -> 0.37596004 | J99: =J98 -> -0.071457626 | K99: =K98 -> 0.059374095 | L99: =L98 -> 0.50900842 | M99: =M98 -> 0.55599671 | N99: =I99+J99*C99+K99*D99+L99*E99+M99*F99 -> 1.0916307 | O99: =1/(1+EXP(-N99)) -> 0.74868868 | P99: =IF(O99>0.5,1,0) -> 1 | Q99: =O99-G99 -> 0.74868868 | R99: =Q99^2 -> 0.56053473 | T99: =IF(P99=G99,1,0) -> 0
B100: 10 | C100: 5 | D100: 3.3 | E100: 1.4 | F100: 0.2 | G100: 0 | I100: =I99 -> 0.37596004 | J100: =J99 -> -0.071457626 | K100: =K99 -> 0.059374095 | L100: =L99 -> 0.50900842 | M100: =M99 -> 0.55599671 | N100: =I100+J100*C100+K100*D100+L100*E100+M100*F100 -> 1.0384175 | O100: =1/(1+EXP(-N100)) -> 0.73854456 | P100: =IF(O100>0.5,1,0) -> 1 | Q100: =O100-G100 -> 0.73854456 | R100: =Q100^2 -> 0.54544806 | T100: =IF(P100=G100,1,0) -> 0
B101: 11 | C101: 5.5 | D101: 2.6 | E101: 4.4 | F101: 1.2 | G101: 1 | I101: =I100 -> 0.37596004 | J101: =J100 -> -0.071457626 | K101: =K100 -> 0.059374095 | L101: =L100 -> 0.50900842 | M101: =M100 -> 0.55599671 | N101: =I101+J101*C101+K101*D101+L101*E101+M101*F101 -> 3.0441488 | O101: =1/(1+EXP(-N101)) -> 0.95452924 | P101: =IF(O101>0.5,1,0) -> 1 | Q101: =O101-G101 -> -0.045470758 | R101: =Q101^2 -> 0.0020675899 | T101: =IF(P101=G101,1,0) -> 1
B102: 12 | C102: 6.1 | D102: 3 | E102: 4.6 | F102: 1.4 | G102: 1 | I102: =I101 -> 0.37596004 | J102: =J101 -> -0.071457626 | K102: =K101 -> 0.059374095 | L102: =L101 -> 0.50900842 | M102: =M101 -> 0.55599671 | N102: =I102+J102*C102+K102*D102+L102*E102+M102*F102 -> 3.2380249 | O102: =1/(1+EXP(-N102)) -> 0.96224041 | P102: =IF(O102>0.5,1,0) -> 1 | Q102: =O102-G102 -> -0.037759587 | R102: =Q102^2 -> 0.0014257864 | T102: =IF(P102=G102,1,0) -> 1
B103: 13 | C103: 5.8 | D103: 2.6 | E103: 4 | F103: 1.2 | G103: 1 | I103: =I102 -> 0.37596004 | J103: =J102 -> -0.071457626 | K103: =K102 -> 0.059374095 | L103: =L102 -> 0.50900842 | M103: =M102 -> 0.55599671 | N103: =I103+J103*C103+K103*D103+L103*E103+M103*F103 -> 2.8191082 | O103: =1/(1+EXP(-N103)) -> 0.9436997 | P103: =IF(O103>0.5,1,0) -> 1 | Q103: =O103-G103 -> -0.056300298 | R103: =Q103^2 -> 0.0031697235 | T103: =IF(P103=G103,1,0) -> 1
... B110: 20 | C110: 5.7 | D110: 2.8 | E110: 4.1 | F110: 1.3 | G110: 1 | I110: =I109 -> 0.37596004 | J110: =J109 -> -0.071457626 | K110: =K109 -> 0.059374095 | L110: =L109 -> 0.50900842 | M110: =M109 -> 0.55599671 | N110: =I110+J110*C110+K110*D110+L110*E110+M110*F110 -> 2.9446293 | O110: =1/(1+EXP(-N110)) -> 0.95000904 | P110: =IF(O110>0.5,1,0) -> 1 | Q110: =O110-G110 -> -0.049990962 | R110: =Q110^2 -> 0.0024990963 | T110: =IF(P110=G110,1,0) -> 1
Q111: MSE → | R111: =AVERAGE(R91:R110) -> 0.28755158 | T111: =AVERAGE(T91:T110) -> 0.5
A113: Confusion Matrix (data testing) | I113: Evaluation Metrics
C114: Prediksi | I114: Metrik | J114: Hasil (%)
...

Sheet Epoch 2
A1: EPOCH 2 — TRAINING (80 data)
G2: Setosa = 0 | I2: Learning Rate | K2: ='Konfigurasi Model'!$B$11 -> 0.1
G3: Versicolor = 1 | I3: Bobot bias | N3: dot | O3: Sigmoid | P3: Prediksi | Q3: error | R3: Sum Square Error
A4: EPOCH | B4: No | C4: X1 | D4: X2 | E4: X3 | F4: X4 | G4: TARGET | I4: bias | J4: teta1 | K4: teta2 | L4: teta 3 | M4: teta4 | N4: z | O4: g(z) | T4: dbias | U4: dteta1 | V4: dteta2 | W4: dteta3 | X4: dteta4 | Y4: Akurasi
A5: epoch 2 | B5: 1 | C5: 5.1 | D5: 3.5 | E5: 1.4 | F5: 0.2 | G5: 0 | I5: ='Epoch 1'!I84 -> 0.37596004 | J5: ='Epoch 1'!J84 -> -0.071457626 | K5: ='Epoch 1'!K84 -> 0.059374095 | L5: ='Epoch 1'!L84 -> 0.50900842 | M5: ='Epoch 1'!M84 -> 0.55599671 | N5: =I5+J5*C5+K5*D5+L5*E5+M5*F5 -> 1.0431466 | O5: =1/(1+EXP(-N5)) -> 0.73945669 | P5: =IF(O5>0.5,1,0) -> 1 | Q5: =O5-G5 -> 0.73945669 | R5: =Q5^2 -> 0.5467962 | T5: =2*(O5-G5)*(1-O5)*O5 -> 0.28492818 | U5: =2*(O5-G5)*(1-O5)*O5*C5 -> 1.4531337 | V5: =2*(O5-G5)*(1-O5)*O5*D5 -> 0.99724864 | W5: =2*(O5-G5)*(1-O5)*O5*E5 -> 0.39889945 | X5: =2*(O5-G5)*(1-O5)*O5*F5 -> 0.056985636 | Y5: =IF(P5=G5,1,0) -> 0
B6: 2 | C6: 4.9 | D6: 3 | E6: 1.4 | F6: 0.2 | G6: 0 | I6: =I5-('Konfigurasi Model'!$B$11*T5) -> 0.34746722 | J6: =J5-('Konfigurasi Model'!$B$11*U5) -> -0.216771 | K6: =K5-('Konfigurasi Model'!$B$11*V5) -> -0.040350769 | L6: =L5-('Konfigurasi Model'!$B$11*W5) -> 0.46911847 | M6: =M5-('Konfigurasi Model'!$B$11*X5) -> 0.55029815 | N6: =I6+J6*C6+K6*D6+L6*E6+M6*F6 -> -0.06893749 | O6: =1/(1+EXP(-N6)) -> 0.48277245 | P6: =IF(O6>0.5,1,0) -> 0 | Q6: =O6-G6 -> 0.48277245 | R6: =Q6^2 -> 0.23306924 | T6: =2*(O6-G6)*(1-O6)*O6 -> 0.24109966 | U6: =2*(O6-G6)*(1-O6)*O6*C6 -> 1.1813883 | V6: =2*(O6-G6)*(1-O6)*O6*D6 -> 0.72329899 | W6: =2*(O6-G6)*(1-O6)*O6*E6 -> 0.33753953 | X6: =2*(O6-G6)*(1-O6)*O6*F6 -> 0.048219932 | Y6: =IF(P6=G6,1,0) -> 1
B7: 3 | C7: 4.7 | D7: 3.2 | E7: 1.3 | F7: 0.2 | G7: 0 | I7: =I6-('Konfigurasi Model'!$B$11*T6) -> 0.32335726 | J7: =J6-('Konfigurasi Model'!$B$11*U6) -> -0.33490983 | K7: =K6-('Konfigurasi Model'!$B$11*V6) -> -0.11268067 | L7: =L6-('Konfigurasi Model'!$B$11*W6) -> 0.43536452 | M7: =M6-('Konfigurasi Model'!$B$11*X6) -> 0.54547615 | N7: =I7+J7*C7+K7*D7+L7*E7+M7*F7 -> -0.93622799 | O7: =1/(1+EXP(-N7)) -> 0.2816629 | P7: =IF(O7>0.5,1,0) -> 0 | Q7: =O7-G7 -> 0.2816629 | R7: =Q7^2 -> 0.079333989 | T7: =2*(O7-G7)*(1-O7)*O7 -> 0.1139771 | U7: =2*(O7-G7)*(1-O7)*O7*C7 -> 0.53569235 | V7: =2*(O7-G7)*(1-O7)*O7*D7 -> 0.36472671 | W7: =2*(O7-G7)*(1-O7)*O7*E7 -> 0.14817022 | X7: =2*(O7-G7)*(1-O7)*O7*F7 -> 0.022795419 | Y7: =IF(P7=G7,1,0) -> 1
B8: 4 | C8: 4.6 | D8: 3.1 | E8: 1.5 | F8: 0.2 | G8: 0 | I8: =I7-('Konfigurasi Model'!$B$11*T7) -> 0.31195955 | J8: =J7-('Konfigurasi Model'!$B$11*U7) -> -0.38847907 | K8: =K7-('Konfigurasi Model'!$B$11*V7) -> -0.14915334 | L8: =L7-('Konfigurasi Model'!$B$11*W7) -> 0.4205475 | M8: =M7-('Konfigurasi Model'!$B$11*X7) -> 0.54319661 | N8: =I8+J8*C8+K8*D8+L8*E8+M8*F8 -> -1.1979589 | O8: =1/(1+EXP(-N8)) -> 0.23183851 | P8: =IF(O8>0.5,1,0) -> 0 | Q8: =O8-G8 -> 0.23183851 | R8: =Q8^2 -> 0.053749093 | T8: =2*(O8-G8)*(1-O8)*O8 -> 0.082575968 | U8: =2*(O8-G8)*(1-O8)*O8*C8 -> 0.37984945 | V8: =2*(O8-G8)*(1-O8)*O8*D8 -> 0.2559855 | W8: =2*(O8-G8)*(1-O8)*O8*E8 -> 0.12386395 | X8: =2*(O8-G8)*(1-O8)*O8*F8 -> 0.016515194 | Y8: =IF(P8=G8,1,0) -> 1
B9: 5 | C9: 5 | D9: 3.6 | E9: 1.4 | F9: 0.2 | G9: 0 | I9: =I8-('Konfigurasi Model'!$B$11*T8) -> 0.30370195 | J9: =J8-('Konfigurasi Model'!$B$11*U8) -> -0.42646401 | K9: =K8-('Konfigurasi Model'!$B$11*V8) -> -0.17475189 | L9: =L8-('Konfigurasi Model'!$B$11*W8) -> 0.4081611 | M9: =M8-('Konfigurasi Model'!$B$11*X8) -> 0.54154509 | N9: =I9+J9*C9+K9*D9+L9*E9+M9*F9 -> -1.7779904 | O9: =1/(1+EXP(-N9)) -> 0.14455146 | P9: =IF(O9>0.5,1,0) -> 0 | Q9: =O9-G9 -> 0.14455146 | R9: =Q9^2 -> 0.020895125 | T9: =2*(O9-G9)*(1-O9)*O9 -> 0.035749409 | U9: =2*(O9-G9)*(1-O9)*O9*C9 -> 0.17874704 | V9: =2*(O9-G9)*(1-O9)*O9*D9 -> 0.12869787 | W9: =2*(O9-G9)*(1-O9)*O9*E9 -> 0.050049172 | X9: =2*(O9-G9)*(1-O9)*O9*F9 -> 0.0071498817 | Y9: =IF(P9=G9,1,0) -> 1
B10: 6 | C10: 5.4 | D10: 3.9 | E10: 1.7 | F10: 0.4 | G10: 0 | I10: =I9-('Konfigurasi Model'!$B$11*T9) -> 0.30012701 | J10: =J9-('Konfigurasi Model'!$B$11*U9) -> -0.44433872 | K10: =K9-('Konfigurasi Model'!$B$11*V9) -> -0.18762168 | L10: =L9-('Konfigurasi Model'!$B$11*W9) -> 0.40315618 | M10: =M9-('Konfigurasi Model'!$B$11*X9) -> 0.5408301 | N10: =I10+J10*C10+K10*D10+L10*E10+M10*F10 -> -1.929329 | O10: =1/(1+EXP(-N10)) -> 0.12682486 | P10: =IF(O10>0.5,1,0) -> 0 | Q10: =O10-G10 -> 0.12682486 | R10: =Q10^2 -> 0.016084546 | T10: =2*(O10-G10)*(1-O10)*O10 -> 0.028089251 | U10: =2*(O10-G10)*(1-O10)*O10*C10 -> 0.15168196 | V10: =2*(O10-G10)*(1-O10)*O10*D10 -> 0.10954808 | W10: =2*(O10-G10)*(1-O10)*O10*E10 -> 0.047751727 | X10: =2*(O10-G10)*(1-O10)*O10*F10 -> 0.0112357 | Y10: =IF(P10=G10,1,0) -> 1
B11: 7 | C11: 4.6 | D11: 3.4 | E11: 1.4 | F11: 0.3 | G11: 0 | I11: =I10-('Konfigurasi Model'!$B$11*T10) -> 0.29731808 | J11: =J10-('Konfigurasi Model'!$B$11*U10) -> -0.45950691 | K11: =K10-('Konfigurasi Model'!$B$11*V10) -> -0.19857648 | L11: =L10-('Konfigurasi Model'!$B$11*W10) -> 0.39838101 | M11: =M10-('Konfigurasi Model'!$B$11*X10) -> 0.53970653 | N11: =I11+J11*C11+K11*D11+L11*E11+M11*F11 -> -1.7719284 | O11: =1/(1+EXP(-N11)) -> 0.14530268 | P11: =IF(O11>0.5,1,0) -> 0 | Q11: =O11-G11 -> 0.14530268 | R11: =Q11^2 -> 0.021112869 | T11: =2*(O11-G11)*(1-O11)*O11 -> 0.036090225 | U11: =2*(O11-G11)*(1-O11)*O11*C11 -> 0.16601503 | V11: =2*(O11-G11)*(1-O11)*O11*D11 -> 0.12270676 | W11: =2*(O11-G11)*(1-O11)*O11*E11 -> 0.050526314 | X11: =2*(O11-G11)*(1-O11)*O11*F11 -> 0.010827067 | Y11: =IF(P11=G11,1,0) -> 1
B12: 8 | C12: 5 | D12: 3.4 | E12: 1.5 | F12: 0.2 | G12: 0 | I12: =I11-('Konfigurasi Model'!$B$11*T11) -> 0.29370906 | J12: =J11-('Konfigurasi Model'!$B$11*U11) -> -0.47610842 | K12: =K11-('Konfigurasi Model'!$B$11*V11) -> -0.21084716 | L12: =L11-('Konfigurasi Model'!$B$11*W11) -> 0.39332838 | M12: =M11-('Konfigurasi Model'!$B$11*X11) -> 0.53862383 | N12: =I12+J12*C12+K12*D12+L12*E12+M12*F12 -> -2.105996 | O12: =1/(1+EXP(-N12)) -> 0.1085154 | P12: =IF(O12>0.5,1,0) -> 0 | Q12: =O12-G12 -> 0.1085154 | R12: =Q12^2 -> 0.011775593 | T12: =2*(O12-G12)*(1-O12)*O12 -> 0.020995519 | U12: =2*(O12-G12)*(1-O12)*O12*C12 -> 0.1049776 | V12: =2*(O12-G12)*(1-O12)*O12*D12 -> 0.071384765 | W12: =2*(O12-G12)*(1-O12)*O12*E12 -> 0.031493279 | X12: =2*(O12-G12)*(1-O12)*O12*F12 -> 0.0041991038 | Y12: =IF(P12=G12,1,0) -> 1
B13: 9 | C13: 4.4 | D13: 2.9 | E13: 1.4 | F13: 0.2 | G13: 0 | I13: =I12-('Konfigurasi Model'!$B$11*T12) -> 0.29160951 | J13: =J12-('Konfigurasi Model'!$B$11*U12) -> -0.48660618 | K13: =K12-('Konfigurasi Model'!$B$11*V12) -> -0.21798564 | L13: =L12-('Konfigurasi Model'!$B$11*W12) -> 0.39017905 | M13: =M12-('Konfigurasi Model'!$B$11*X12) -> 0.53820392 | N13: =I13+J13*C13+K13*D13+L13*E13+M13*F13 -> -1.8277246 | O13: =1/(1+EXP(-N13)) -> 0.13850957 | P13: =IF(O13>0.5,1,0) -> 0 | Q13: =O13-G13 -> 0.13850957 | R13: =Q13^2 -> 0.0191849 | T13: =2*(O13-G13)*(1-O13)*O13 -> 0.033055216 | U13: =2*(O13-G13)*(1-O13)*O13*C13 -> 0.14544295 | V13: =2*(O13-G13)*(1-O13)*O13*D13 -> 0.095860126 | W13: =2*(O13-G13)*(1-O13)*O13*E13 -> 0.046277302 | X13: =2*(O13-G13)*(1-O13)*O13*F13 -> 0.0066110432 | Y13: =IF(P13=G13,1,0) -> 1
B14: 10 | C14: 4.9 | D14: 3.1 | E14: 1.5 | F14: 0.1 | G14: 0 | I14: =I13-('Konfigurasi Model'!$B$11*T13) -> 0.28830399 | J14: =J13-('Konfigurasi Model'!$B$11*U13) -> -0.50115047 | K14: =K13-('Konfigurasi Model'!$B$11*V13) -> -0.22757165 | L14: =L13-('Konfigurasi Model'!$B$11*W13) -> 0.38555132 | M14: =M13-('Konfigurasi Model'!$B$11*X13) -> 0.53754281 | N14: =I14+J14*C14+K14*D14+L14*E14+M14*F14 -> -2.2407242 | O14: =1/(1+EXP(-N14)) -> 0.096152588 | P14: =IF(O14>0.5,1,0) -> 0 | Q14: =O14-G14 -> 0.096152588 | R14: =Q14^2 -> 0.0092453202 | T14: =2*(O14-G14)*(1-O14)*O14 -> 0.016712717 | U14: =2*(O14-G14)*(1-O14)*O14*C14 -> 0.081892315 | V14: =2*(O14-G14)*(1-O14)*O14*D14 -> 0.051809424 | W14: =2*(O14-G14)*(1-O14)*O14*E14 -> 0.025069076 | X14: =2*(O14-G14)*(1-O14)*O14*F14 -> 0.0016712717 | Y14: =IF(P14=G14,1,0) -> 1
B15: 11 | C15: 5.4 | D15: 3.7 | E15: 1.5 | F15: 0.2 | G15: 0 | I15: =I14-('Konfigurasi Model'!$B$11*T14) -> 0.28663272 | J15: =J14-('Konfigurasi Model'!$B$11*U14) -> -0.5093397 | K15: =K14-('Konfigurasi Model'!$B$11*V14) -> -0.23275259 | L15: =L14-('Konfigurasi Model'!$B$11*W14) -> 0.38304441 | M15: =M14-('Konfigurasi Model'!$B$11*X14) -> 0.53737569 | N15: =I15+J15*C15+K15*D15+L15*E15+M15*F15 -> -2.6429445 | O15: =1/(1+EXP(-N15)) -> 0.066425205 | P15: =IF(O15>0.5,1,0) -> 0 | Q15: =O15-G15 -> 0.066425205 | R15: =Q15^2 -> 0.0044123078 | T15: =2*(O15-G15)*(1-O15)*O15 -> 0.0082384388 | U15: =2*(O15-G15)*(1-O15)*O15*C15 -> 0.044487569 | V15: =2*(O15-G15)*(1-O15)*O15*D15 -> 0.030482224 | W15: =2*(O15-G15)*(1-O15)*O15*E15 -> 0.012357658 | X15: =2*(O15-G15)*(1-O15)*O15*F15 -> 0.0016476878 | Y15: =IF(P15=G15,1,0) -> 1
B16: 12 | C16: 4.8 | D16: 3.4 | E16: 1.6 | F16: 0.2 | G16: 0 | I16: =I15-('Konfigurasi Model'!$B$11*T15) -> 0.28580887 | J16: =J15-('Konfigurasi Model'!$B$11*U15) -> -0.51378846 | K16: =K15-('Konfigurasi Model'!$B$11*V15) -> -0.23580081 | L16: =L15-('Konfigurasi Model'!$B$11*W15) -> 0.38180865 | M16: =M15-('Konfigurasi Model'!$B$11*X15) -> 0.53721092 | N16: =I16+J16*C16+K16*D16+L16*E16+M16*F16 -> -2.2637625 | O16: =1/(1+EXP(-N16)) -> 0.094168935 | P16: =IF(O16>0.5,1,0) -> 0 | Q16: =O16-G16 -> 0.094168935 | R16: =Q16^2 -> 0.0088677883 | T16: =2*(O16-G16)*(1-O16)*O16 -> 0.016065436 | U16: =2*(O16-G16)*(1-O16)*O16*C16 -> 0.077114094 | V16: =2*(O16-G16)*(1-O16)*O16*D16 -> 0.054622483 | W16: =2*(O16-G16)*(1-O16)*O16*E16 -> 0.025704698 | X16: =2*(O16-G16)*(1-O16)*O16*F16 -> 0.0032130872 | Y16: =IF(P16=G16,1,0) -> 1
B17: 13 | C17: 4.8 | D17: 3 | E17: 1.4 | F17: 0.1 | G17: 0 | I17: =I16-('Konfigurasi Model'!$B$11*T16) -> 0.28420233 | J17: =J16-('Konfigurasi Model'!$B$11*U16) -> -0.52149987 | K17: =K16-('Konfigurasi Model'!$B$11*V16) -> -0.24126306 | L17: =L16-('Konfigurasi Model'!$B$11*W16) -> 0.37923818 | M17: =M16-('Konfigurasi Model'!$B$11*X16) -> 0.53688961 | N17: =I17+J17*C17+K17*D17+L17*E17+M17*F17 -> -2.3581638 | O17: =1/(1+EXP(-N17)) -> 0.086419053 | P17: =IF(O17>0.5,1,0) -> 0 | Q17: =O17-G17 -> 0.086419053 | R17: =Q17^2 -> 0.0074682527 | T17: =2*(O17-G17)*(1-O17)*O17 -> 0.013645707 | U17: =2*(O17-G17)*(1-O17)*O17*C17 -> 0.065499392 | V17: =2*(O17-G17)*(1-O17)*O17*D17 -> 0.04093712 | W17: =2*(O17-G17)*(1-O17)*O17*E17 -> 0.019103989 | X17: =2*(O17-G17)*(1-O17)*O17*F17 -> 0.0013645707 | Y17: =IF(P17=G17,1,0) -> 1
... B84: 80 | C84: 5.5 | D84: 2.5 | E84: 4 | F84: 1.3 | G84: 1 | I84: =I83-('Konfigurasi Model'!$B$11*T83) -> 0.32179489 | J84: =J83-('Konfigurasi Model'!$B$11*U83) -> -0.19188487 | K84: =K83-('Konfigurasi Model'!$B$11*V83) -> -0.16763045 | L84: =L83-('Konfigurasi Model'!$B$11*W83) -> 0.80316279 | M84: =M83-('Konfigurasi Model'!$B$11*X83) -> 0.6981889 | N84: =I84+J84*C84+K84*D84+L84*E84+M84*F84 -> 2.9676487 | O84: =1/(1+EXP(-N84)) -> 0.95109102 | P84: =IF(O84>0.5,1,0) -> 1 | Q84: =O84-G84 -> -0.048908981 | R84: =Q84^2 -> 0.0023920885 | T84: =2*(O84-G84)*(1-O84)*O84 -> -0.0045501877 | U84: =2*(O84-G84)*(1-O84)*O84*C84 -> -0.025026032 | V84: =2*(O84-G84)*(1-O84)*O84*D84 -> -0.011375469 | W84: =2*(O84-G84)*(1-O84)*O84*E84 -> -0.018200751 | X84: =2*(O84-G84)*(1-O84)*O84*F84 -> -0.005915244 | Y84: =IF(P84=G84,1,0) -> 1
Q85: MSE → | R85: =AVERAGE(R5:R84) -> 0.044862842 | X85: Akurasi → | Y85: =AVERAGE(Y5:Y84) -> 0.9375
A87: EPOCH 2 — TESTING (20 data, bobot = baris 84)
G88: Setosa = 0 | I88: Learning Rate | K88: ='Konfigurasi Model'!$B$11 -> 0.1
G89: Versicolor = 1 | I89: Bobot bias | N89: dot | O89: Sigmoid | P89: Prediksi | Q89: error | R89: Sum Square Error
A90: EPOCH | B90: No | C90: X1 | D90: X2 | E90: X3 | F90: X4 | G90: TARGET | I90: bias | J90: teta1 | K90: teta2 | L90: teta 3 | M90: teta4 | N90: z | O90: g(z) | T90: Akurasi
A91: testing | B91: 1 | C91: 5 | D91: 3.5 | E91: 1.3 | F91: 0.3 | G91: 0 | I91: =I84 -> 0.32179489 | J91: =J84 -> -0.19188487 | K91: =K84 -> -0.16763045 | L91: =L84 -> 0.80316279 | M91: =M84 -> 0.6981889 | N91: =I91+J91*C91+K91*D91+L91*E91+M91*F91 -> 0.029232257 | O91: =1/(1+EXP(-N91)) -> 0.50730754 | P91: =IF(O91>0.5,1,0) -> 1 | Q91: =O91-G91 -> 0.50730754 | R91: =Q91^2 -> 0.25736094 | T91: =IF(P91=G91,1,0) -> 0
B92: 2 | C92: 4.5 | D92: 2.3 | E92: 1.3 | F92: 0.3 | G92: 0 | I92: =I91 -> 0.32179489 | J92: =J91 -> -0.19188487 | K92: =K91 -> -0.16763045 | L92: =L91 -> 0.80316279 | M92: =M91 -> 0.6981889 | N92: =I92+J92*C92+K92*D92+L92*E92+M92*F92 -> 0.32633123 | O92: =1/(1+EXP(-N92)) -> 0.58086644 | P92: =IF(O92>0.5,1,0) -> 1 | Q92: =O92-G92 -> 0.58086644 | R92: =Q92^2 -> 0.33740582 | T92: =IF(P92=G92,1,0) -> 0
B93: 3 | C93: 4.4 | D93: 3.2 | E93: 1.3 | F93: 0.2 | G93: 0 | I93: =I92 -> 0.32179489 | J93: =J92 -> -0.19188487 | K93: =K92 -> -0.16763045 | L93: =L92 -> 0.80316279 | M93: =M92 -> 0.6981889 | N93: =I93+J93*C93+K93*D93+L93*E93+M93*F93 -> 0.12483342 | O93: =1/(1+EXP(-N93)) -> 0.53116789 | P93: =IF(O93>0.5,1,0) -> 1 | Q93: =O93-G93 -> 0.53116789 | R93: =Q93^2 -> 0.28213933 | T93: =IF(P93=G93,1,0) -> 0
B94: 4 | C94: 5 | D94: 3.5 | E94: 1.6 | F94: 0.6 | G94: 0 | I94: =I93 -> 0.32179489 | J94: =J93 -> -0.19188487 | K94: =K93 -> -0.16763045 | L94: =L93 -> 0.80316279 | M94: =M93 -> 0.6981889 | N94: =I94+J94*C94+K94*D94+L94*E94+M94*F94 -> 0.47963777 | O94: =1/(1+EXP(-N94)) -> 0.61766233 | P94: =IF(O94>0.5,1,0) -> 1 | Q94: =O94-G94 -> 0.61766233 | R94: =Q94^2 -> 0.38150676 | T94: =IF(P94=G94,1,0) -> 0
B95: 5 | C95: 5.1 | D95: 3.8 | E95: 1.9 | F95: 0.4 | G95: 0 | I95: =I94 -> 0.32179489 | J95: =J94 -> -0.19188487 | K95: =K94 -> -0.16763045 | L95: =L94 -> 0.80316279 | M95: =M94 -> 0.6981889 | N95: =I95+J95*C95+K95*D95+L95*E95+M95*F95 -> 0.5114712 | O95: =1/(1+EXP(-N95)) -> 0.6251513 | P95: =IF(O95>0.5,1,0) -> 1 | Q95: =O95-G95 -> 0.6251513 | R95: =Q95^2 -> 0.39081414 | T95: =IF(P95=G95,1,0) -> 0
B96: 6 | C96: 4.8 | D96: 3 | E96: 1.4 | F96: 0.3 | G96: 0 | I96: =I95 -> 0.32179489 | J96: =J95 -> -0.19188487 | K96: =K95 -> -0.16763045 | L96: =L95 -> 0.80316279 | M96: =M95 -> 0.6981889 | N96: =I96+J96*C96+K96*D96+L96*E96+M96*F96 -> 0.23174074 | O96: =1/(1+EXP(-N96)) -> 0.55767729 | P96: =IF(O96>0.5,1,0) -> 1 | Q96: =O96-G96 -> 0.55767729 | R96: =Q96^2 -> 0.31100396 | T96: =IF(P96=G96,1,0) -> 0
B97: 7 | C97: 5.1 | D97: 3.8 | E97: 1.6 | F97: 0.2 | G97: 0 | I97: =I96 -> 0.32179489 | J97: =J96 -> -0.19188487 | K97: =K96 -> -0.16763045 | L97: =L96 -> 0.80316279 | M97: =M96 -> 0.6981889 | N97: =I97+J97*C97+K97*D97+L97*E97+M97*F97 -> 0.13088458 | O97: =1/(1+EXP(-N97)) -> 0.53267451 | P97: =IF(O97>0.5,1,0) -> 1 | Q97: =O97-G97 -> 0.53267451 | R97: =Q97^2 -> 0.28374214 | T97: =IF(P97=G97,1,0) -> 0
B98: 8 | C98: 4.6 | D98: 3.2 | E98: 1.4 | F98: 0.2 | G98: 0 | I98: =I97 -> 0.32179489 | J98: =J97 -> -0.19188487 | K98: =K97 -> -0.16763045 | L98: =L97 -> 0.80316279 | M98: =M97 -> 0.6981889 | N98: =I98+J98*C98+K98*D98+L98*E98+M98*F98 -> 0.16677273 | O98: =1/(1+EXP(-N98)) -> 0.54159682 | P98: =IF(O98>0.5,1,0) -> 1 | Q98: =O98-G98 -> 0.54159682 | R98: =Q98^2 -> 0.29332711 | T98: =IF(P98=G98,1,0) -> 0
B99: 9 | C99: 5.3 | D99: 3.7 | E99: 1.5 | F99: 0.2 | G99: 0 | I99: =I98 -> 0.32179489 | J99: =J98 -> -0.19188487 | K99: =K98 -> -0.16763045 | L99: =L98 -> 0.80316279 | M99: =M98 -> 0.6981889 | N99: =I99+J99*C99+K99*D99+L99*E99+M99*F99 -> 0.028954374 | O99: =1/(1+EXP(-N99)) -> 0.50723809 | P99: =IF(O99>0.5,1,0) -> 1 | Q99: =O99-G99 -> 0.50723809 | R99: =Q99^2 -> 0.25729048 | T99: =IF(P99=G99,1,0) -> 0
B100: 10 | C100: 5 | D100: 3.3 | E100: 1.4 | F100: 0.2 | G100: 0 | I100: =I99 -> 0.32179489 | J100: =J99 -> -0.19188487 | K100: =K99 -> -0.16763045 | L100: =L99 -> 0.80316279 | M100: =M99 -> 0.6981889 | N100: =I100+J100*C100+K100*D100+L100*E100+M100*F100 -> 0.073255736 | O100: =1/(1+EXP(-N100)) -> 0.51830575 | P100: =IF(O100>0.5,1,0) -> 1 | Q100: =O100-G100 -> 0.51830575 | R100: =Q100^2 -> 0.26864085 | T100: =IF(P100=G100,1,0) -> 0
B101: 11 | C101: 5.5 | D101: 2.6 | E101: 4.4 | F101: 1.2 | G101: 1 | I101: =I100 -> 0.32179489 | J101: =J100 -> -0.19188487 | K101: =K100 -> -0.16763045 | L101: =L100 -> 0.80316279 | M101: =M100 -> 0.6981889 | N101: =I101+J101*C101+K101*D101+L101*E101+M101*F101 -> 3.2023319 | O101: =1/(1+EXP(-N101)) -> 0.96092194 | P101: =IF(O101>0.5,1,0) -> 1 | Q101: =O101-G101 -> -0.039078063 | R101: =Q101^2 -> 0.001527095 | T101: =IF(P101=G101,1,0) -> 1
B102: 12 | C102: 6.1 | D102: 3 | E102: 4.6 | F102: 1.4 | G102: 1 | I102: =I101 -> 0.32179489 | J102: =J101 -> -0.19188487 | K102: =K101 -> -0.16763045 | L102: =L101 -> 0.80316279 | M102: =M101 -> 0.6981889 | N102: =I102+J102*C102+K102*D102+L102*E102+M102*F102 -> 3.3204191 | O102: =1/(1+EXP(-N102)) -> 0.9651227 | P102: =IF(O102>0.5,1,0) -> 1 | Q102: =O102-G102 -> -0.034877297 | R102: =Q102^2 -> 0.0012164259 | T102: =IF(P102=G102,1,0) -> 1
B103: 13 | C103: 5.8 | D103: 2.6 | E103: 4 | F103: 1.2 | G103: 1 | I103: =I102 -> 0.32179489 | J103: =J102 -> -0.19188487 | K103: =K102 -> -0.16763045 | L103: =L102 -> 0.80316279 | M103: =M102 -> 0.6981889 | N103: =I103+J103*C103+K103*D103+L103*E103+M103*F103 -> 2.8235013 | O103: =1/(1+EXP(-N103)) -> 0.94393266 | P103: =IF(O103>0.5,1,0) -> 1 | Q103: =O103-G103 -> -0.056067342 | R103: =Q103^2 -> 0.0031435468 | T103: =IF(P103=G103,1,0) -> 1
... B110: 20 | C110: 5.7 | D110: 2.8 | E110: 4.1 | F110: 1.3 | G110: 1 | I110: =I109 -> 0.32179489 | J110: =J109 -> -0.19188487 | K110: =K109 -> -0.16763045 | L110: =L109 -> 0.80316279 | M110: =M109 -> 0.6981889 | N110: =I110+J110*C110+K110*D110+L110*E110+M110*F110 -> 2.9592989 | O110: =1/(1+EXP(-N110)) -> 0.95070114 | P110: =IF(O110>0.5,1,0) -> 1 | Q110: =O110-G110 -> -0.049298856 | R110: =Q110^2 -> 0.0024303772 | T110: =IF(P110=G110,1,0) -> 1
Q111: MSE → | R111: =AVERAGE(R91:R110) -> 0.15501014 | T111: =AVERAGE(T91:T110) -> 0.5
A113: Confusion Matrix (data testing) | I113: Evaluation Metrics
C114: Prediksi | I114: Metrik | J114: Hasil (%)
...

Sheet Epoch 3
A1: EPOCH 3 — TRAINING (80 data)
G2: Setosa = 0 | I2: Learning Rate | K2: ='Konfigurasi Model'!$B$11 -> 0.1
G3: Versicolor = 1 | I3: Bobot bias | N3: dot | O3: Sigmoid | P3: Prediksi | Q3: error | R3: Sum Square Error
A4: EPOCH | B4: No | C4: X1 | D4: X2 | E4: X3 | F4: X4 | G4: TARGET | I4: bias | J4: teta1 | K4: teta2 | L4: teta 3 | M4: teta4 | N4: z | O4: g(z) | T4: dbias | U4: dteta1 | V4: dteta2 | W4: dteta3 | X4: dteta4 | Y4: Akurasi
A5: epoch 3 | B5: 1 | C5: 5.1 | D5: 3.5 | E5: 1.4 | F5: 0.2 | G5: 0 | I5: ='Epoch 2'!I84 -> 0.32179489 | J5: ='Epoch 2'!J84 -> -0.19188487 | K5: ='Epoch 2'!K84 -> -0.16763045 | L5: ='Epoch 2'!L84 -> 0.80316279 | M5: ='Epoch 2'!M84 -> 0.6981889 | N5: =I5+J5*C5+K5*D5+L5*E5+M5*F5 -> 0.020541159 | O5: =1/(1+EXP(-N5)) -> 0.50513511 | P5: =IF(O5>0.5,1,0) -> 1 | Q5: =O5-G5 -> 0.50513511 | R5: =Q5^2 -> 0.25516148 | T5: =2*(O5-G5)*(1-O5)*O5 -> 0.25254091 | U5: =2*(O5-G5)*(1-O5)*O5*C5 -> 1.2879587 | V5: =2*(O5-G5)*(1-O5)*O5*D5 -> 0.8838932 | W5: =2*(O5-G5)*(1-O5)*O5*E5 -> 0.35355728 | X5: =2*(O5-G5)*(1-O5)*O5*F5 -> 0.050508183 | Y5: =IF(P5=G5,1,0) -> 0
B6: 2 | C6: 4.9 | D6: 3 | E6: 1.4 | F6: 0.2 | G6: 0 | I6: =I5-('Konfigurasi Model'!$B$11*T5) -> 0.2965408 | J6: =J5-('Konfigurasi Model'!$B$11*U5) -> -0.32068074 | K6: =K5-('Konfigurasi Model'!$B$11*V5) -> -0.25601977 | L6: =L5-('Konfigurasi Model'!$B$11*W5) -> 0.76780707 | M6: =M5-('Konfigurasi Model'!$B$11*X5) -> 0.69313809 | N6: =I6+J6*C6+K6*D6+L6*E6+M6*F6 -> -0.82929662 | O6: =1/(1+EXP(-N6)) -> 0.30379382 | P6: =IF(O6>0.5,1,0) -> 0 | Q6: =O6-G6 -> 0.30379382 | R6: =Q6^2 -> 0.092290683 | T6: =2*(O6-G6)*(1-O6)*O6 -> 0.12850669 | U6: =2*(O6-G6)*(1-O6)*O6*C6 -> 0.62968277 | V6: =2*(O6-G6)*(1-O6)*O6*D6 -> 0.38552006 | W6: =2*(O6-G6)*(1-O6)*O6*E6 -> 0.17990936 | X6: =2*(O6-G6)*(1-O6)*O6*F6 -> 0.025701338 | Y6: =IF(P6=G6,1,0) -> 1
B7: 3 | C7: 4.7 | D7: 3.2 | E7: 1.3 | F7: 0.2 | G7: 0 | I7: =I6-('Konfigurasi Model'!$B$11*T6) -> 0.28369013 | J7: =J6-('Konfigurasi Model'!$B$11*U6) -> -0.38364901 | K7: =K6-('Konfigurasi Model'!$B$11*V6) -> -0.29457178 | L7: =L6-('Konfigurasi Model'!$B$11*W6) -> 0.74981613 | M7: =M6-('Konfigurasi Model'!$B$11*X6) -> 0.69056795 | N7: =I7+J7*C7+K7*D7+L7*E7+M7*F7 -> -1.3492154 | O7: =1/(1+EXP(-N7)) -> 0.20599868 | P7: =IF(O7>0.5,1,0) -> 0 | Q7: =O7-G7 -> 0.20599868 | R7: =Q7^2 -> 0.042435456 | T7: =2*(O7-G7)*(1-O7)*O7 -> 0.067387616 | U7: =2*(O7-G7)*(1-O7)*O7*C7 -> 0.31672179 | V7: =2*(O7-G7)*(1-O7)*O7*D7 -> 0.21564037 | W7: =2*(O7-G7)*(1-O7)*O7*E7 -> 0.0876039 | X7: =2*(O7-G7)*(1-O7)*O7*F7 -> 0.013477523 | Y7: =IF(P7=G7,1,0) -> 1
B8: 4 | C8: 4.6 | D8: 3.1 | E8: 1.5 | F8: 0.2 | G8: 0 | I8: =I7-('Konfigurasi Model'!$B$11*T7) -> 0.27695137 | J8: =J7-('Konfigurasi Model'!$B$11*U7) -> -0.41532119 | K8: =K7-('Konfigurasi Model'!$B$11*V7) -> -0.31613581 | L8: =L7-('Konfigurasi Model'!$B$11*W7) -> 0.74105574 | M8: =M7-('Konfigurasi Model'!$B$11*X7) -> 0.6892202 | N8: =I8+J8*C8+K8*D8+L8*E8+M8*F8 -> -1.3641195 | O8: =1/(1+EXP(-N8)) -> 0.20357159 | P8: =IF(O8>0.5,1,0) -> 0 | Q8: =O8-G8 -> 0.20357159 | R8: =Q8^2 -> 0.041441393 | T8: =2*(O8-G8)*(1-O8)*O8 -> 0.066010205 | U8: =2*(O8-G8)*(1-O8)*O8*C8 -> 0.30364694 | V8: =2*(O8-G8)*(1-O8)*O8*D8 -> 0.20463163 | W8: =2*(O8-G8)*(1-O8)*O8*E8 -> 0.099015307 | X8: =2*(O8-G8)*(1-O8)*O8*F8 -> 0.013202041 | Y8: =IF(P8=G8,1,0) -> 1
B9: 5 | C9: 5 | D9: 3.6 | E9: 1.4 | F9: 0.2 | G9: 0 | I9: =I8-('Konfigurasi Model'!$B$11*T8) -> 0.27035035 | J9: =J8-('Konfigurasi Model'!$B$11*U8) -> -0.44568589 | K9: =K8-('Konfigurasi Model'!$B$11*V8) -> -0.33659898 | L9: =L8-('Konfigurasi Model'!$B$11*W8) -> 0.73115421 | M9: =M8-('Konfigurasi Model'!$B$11*X8) -> 0.68789999 | N9: =I9+J9*C9+K9*D9+L9*E9+M9*F9 -> -2.0086395 | O9: =1/(1+EXP(-N9)) -> 0.11829881 | P9: =IF(O9>0.5,1,0) -> 0 | Q9: =O9-G9 -> 0.11829881 | R9: =Q9^2 -> 0.013994608 | T9: =2*(O9-G9)*(1-O9)*O9 -> 0.024678125 | U9: =2*(O9-G9)*(1-O9)*O9*C9 -> 0.12339062 | V9: =2*(O9-G9)*(1-O9)*O9*D9 -> 0.088841249 | W9: =2*(O9-G9)*(1-O9)*O9*E9 -> 0.034549375 | X9: =2*(O9-G9)*(1-O9)*O9*F9 -> 0.004935625 | Y9: =IF(P9=G9,1,0) -> 1
B10: 6 | C10: 5.4 | D10: 3.9 | E10: 1.7 | F10: 0.4 | G10: 0 | I10: =I9-('Konfigurasi Model'!$B$11*T9) -> 0.26788253 | J10: =J9-('Konfigurasi Model'!$B$11*U9) -> -0.45802495 | K10: =K9-('Konfigurasi Model'!$B$11*V9) -> -0.3454831 | L10: =L9-('Konfigurasi Model'!$B$11*W9) -> 0.72769927 | M10: =M9-('Konfigurasi Model'!$B$11*X9) -> 0.68740643 | N10: =I10+J10*C10+K10*D10+L10*E10+M10*F10 -> -2.040785 | O10: =1/(1+EXP(-N10)) -> 0.11498683 | P10: =IF(O10>0.5,1,0) -> 0 | Q10: =O10-G10 -> 0.11498683 | R10: =Q10^2 -> 0.01322197 | T10: =2*(O10-G10)*(1-O10)*O10 -> 0.023403235 | U10: =2*(O10-G10)*(1-O10)*O10*C10 -> 0.12637747 | V10: =2*(O10-G10)*(1-O10)*O10*D10 -> 0.091272618 | W10: =2*(O10-G10)*(1-O10)*O10*E10 -> 0.0397855 | X10: =2*(O10-G10)*(1-O10)*O10*F10 -> 0.0093612942 | Y10: =IF(P10=G10,1,0) -> 1
B11: 7 | C11: 4.6 | D11: 3.4 | E11: 1.4 | F11: 0.3 | G11: 0 | I11: =I10-('Konfigurasi Model'!$B$11*T10) -> 0.26554221 | J11: =J10-('Konfigurasi Model'!$B$11*U10) -> -0.4706627 | K11: =K10-('Konfigurasi Model'!$B$11*V10) -> -0.35461036 | L11: =L10-('Konfigurasi Model'!$B$11*W10) -> 0.72372072 | M11: =M10-('Konfigurasi Model'!$B$11*X10) -> 0.6864703 | N11: =I11+J11*C11+K11*D11+L11*E11+M11*F11 -> -1.8860313 | O11: =1/(1+EXP(-N11)) -> 0.13169764 | P11: =IF(O11>0.5,1,0) -> 0 | Q11: =O11-G11 -> 0.13169764 | R11: =Q11^2 -> 0.017344267 | T11: =2*(O11-G11)*(1-O11)*O11 -> 0.030120137 | U11: =2*(O11-G11)*(1-O11)*O11*C11 -> 0.13855263 | V11: =2*(O11-G11)*(1-O11)*O11*D11 -> 0.10240846 | W11: =2*(O11-G11)*(1-O11)*O11*E11 -> 0.042168191 | X11: =2*(O11-G11)*(1-O11)*O11*F11 -> 0.009036041 | Y11: =IF(P11=G11,1,0) -> 1
B12: 8 | C12: 5 | D12: 3.4 | E12: 1.5 | F12: 0.2 | G12: 0 | I12: =I11-('Konfigurasi Model'!$B$11*T11) -> 0.2625302 | J12: =J11-('Konfigurasi Model'!$B$11*U11) -> -0.48451796 | K12: =K11-('Konfigurasi Model'!$B$11*V11) -> -0.36485121 | L12: =L11-('Konfigurasi Model'!$B$11*W11) -> 0.7195039 | M12: =M11-('Konfigurasi Model'!$B$11*X11) -> 0.6855667 | N12: =I12+J12*C12+K12*D12+L12*E12+M12*F12 -> -2.1841845 | O12: =1/(1+EXP(-N12)) -> 0.10117974 | P12: =IF(O12>0.5,1,0) -> 0 | Q12: =O12-G12 -> 0.10117974 | R12: =Q12^2 -> 0.01023734 | T12: =2*(O12-G12)*(1-O12)*O12 -> 0.018403057 | U12: =2*(O12-G12)*(1-O12)*O12*C12 -> 0.092015286 | V12: =2*(O12-G12)*(1-O12)*O12*D12 -> 0.062570394 | W12: =2*(O12-G12)*(1-O12)*O12*E12 -> 0.027604586 | X12: =2*(O12-G12)*(1-O12)*O12*F12 -> 0.0036806114 | Y12: =IF(P12=G12,1,0) -> 1
B13: 9 | C13: 4.4 | D13: 2.9 | E13: 1.4 | F13: 0.2 | G13: 0 | I13: =I12-('Konfigurasi Model'!$B$11*T12) -> 0.26068989 | J13: =J12-('Konfigurasi Model'!$B$11*U12) -> -0.49371949 | K13: =K12-('Konfigurasi Model'!$B$11*V12) -> -0.37110825 | L13: =L12-('Konfigurasi Model'!$B$11*W12) -> 0.71674344 | M13: =M12-('Konfigurasi Model'!$B$11*X12) -> 0.68519864 | N13: =I13+J13*C13+K13*D13+L13*E13+M13*F13 -> -1.8474092 | O13: =1/(1+EXP(-N13)) -> 0.13617737 | P13: =IF(O13>0.5,1,0) -> 0 | Q13: =O13-G13 -> 0.13617737 | R13: =Q13^2 -> 0.018544276 | T13: =2*(O13-G13)*(1-O13)*O13 -> 0.03203793 | U13: =2*(O13-G13)*(1-O13)*O13*C13 -> 0.14096689 | V13: =2*(O13-G13)*(1-O13)*O13*D13 -> 0.092909998 | W13: =2*(O13-G13)*(1-O13)*O13*E13 -> 0.044853102 | X13: =2*(O13-G13)*(1-O13)*O13*F13 -> 0.006407586 | Y13: =IF(P13=G13,1,0) -> 1
B14: 10 | C14: 4.9 | D14: 3.1 | E14: 1.5 | F14: 0.1 | G14: 0 | I14: =I13-('Konfigurasi Model'!$B$11*T13) -> 0.2574861 | J14: =J13-('Konfigurasi Model'!$B$11*U13) -> -0.50781618 | K14: =K13-('Konfigurasi Model'!$B$11*V13) -> -0.38039925 | L14: =L13-('Konfigurasi Model'!$B$11*W13) -> 0.71225813 | M14: =M13-('Konfigurasi Model'!$B$11*X13) -> 0.68455788 | N14: =I14+J14*C14+K14*D14+L14*E14+M14*F14 -> -2.2732079 | O14: =1/(1+EXP(-N14)) -> 0.093366315 | P14: =IF(O14>0.5,1,0) -> 0 | Q14: =O14-G14 -> 0.093366315 | R14: =Q14^2 -> 0.0087172688 | T14: =2*(O14-G14)*(1-O14)*O14 -> 0.015806739 | U14: =2*(O14-G14)*(1-O14)*O14*C14 -> 0.077453021 | V14: =2*(O14-G14)*(1-O14)*O14*D14 -> 0.049000891 | W14: =2*(O14-G14)*(1-O14)*O14*E14 -> 0.023710109 | X14: =2*(O14-G14)*(1-O14)*O14*F14 -> 0.0015806739 | Y14: =IF(P14=G14,1,0) -> 1
B15: 11 | C15: 5.4 | D15: 3.7 | E15: 1.5 | F15: 0.2 | G15: 0 | I15: =I14-('Konfigurasi Model'!$B$11*T14) -> 0.25590542 | J15: =J14-('Konfigurasi Model'!$B$11*U14) -> -0.51556148 | K15: =K14-('Konfigurasi Model'!$B$11*V14) -> -0.38529934 | L15: =L14-('Konfigurasi Model'!$B$11*W14) -> 0.70988712 | M15: =M14-('Konfigurasi Model'!$B$11*X14) -> 0.68439981 | N15: =I15+J15*C15+K15*D15+L15*E15+M15*F15 -> -2.7520235 | O15: =1/(1+EXP(-N15)) -> 0.059972473 | P15: =IF(O15>0.5,1,0) -> 0 | Q15: =O15-G15 -> 0.059972473 | R15: =Q15^2 -> 0.0035966975 | T15: =2*(O15-G15)*(1-O15)*O15 -> 0.0067619894 | U15: =2*(O15-G15)*(1-O15)*O15*C15 -> 0.036514743 | V15: =2*(O15-G15)*(1-O15)*O15*D15 -> 0.025019361 | W15: =2*(O15-G15)*(1-O15)*O15*E15 -> 0.010142984 | X15: =2*(O15-G15)*(1-O15)*O15*F15 -> 0.0013523979 | Y15: =IF(P15=G15,1,0) -> 1
B16: 12 | C16: 4.8 | D16: 3.4 | E16: 1.6 | F16: 0.2 | G16: 0 | I16: =I15-('Konfigurasi Model'!$B$11*T15) -> 0.25522922 | J16: =J15-('Konfigurasi Model'!$B$11*U15) -> -0.51921296 | K16: =K15-('Konfigurasi Model'!$B$11*V15) -> -0.38780128 | L16: =L15-('Konfigurasi Model'!$B$11*W15) -> 0.70887282 | M16: =M15-('Konfigurasi Model'!$B$11*X15) -> 0.68426457 | N16: =I16+J16*C16+K16*D16+L16*E16+M16*F16 -> -2.2844679 | O16: =1/(1+EXP(-N16)) -> 0.092417521 | P16: =IF(O16>0.5,1,0) -> 0 | Q16: =O16-G16 -> 0.092417521 | R16: =Q16^2 -> 0.0085409982 | T16: =2*(O16-G16)*(1-O16)*O16 -> 0.015503321 | U16: =2*(O16-G16)*(1-O16)*O16*C16 -> 0.074415939 | V16: =2*(O16-G16)*(1-O16)*O16*D16 -> 0.05271129 | W16: =2*(O16-G16)*(1-O16)*O16*E16 -> 0.024805313 | X16: =2*(O16-G16)*(1-O16)*O16*F16 -> 0.0031006641 | Y16: =IF(P16=G16,1,0) -> 1
B17: 13 | C17: 4.8 | D17: 3 | E17: 1.4 | F17: 0.1 | G17: 0 | I17: =I16-('Konfigurasi Model'!$B$11*T16) -> 0.25367889 | J17: =J16-('Konfigurasi Model'!$B$11*U16) -> -0.52665455 | K17: =K16-('Konfigurasi Model'!$B$11*V16) -> -0.3930724 | L17: =L16-('Konfigurasi Model'!$B$11*W16) -> 0.70639229 | M17: =M16-('Konfigurasi Model'!$B$11*X16) -> 0.68395451 | N17: =I17+J17*C17+K17*D17+L17*E17+M17*F17 -> -2.3961355 | O17: =1/(1+EXP(-N17)) -> 0.083467859 | P17: =IF(O17>0.5,1,0) -> 0 | Q17: =O17-G17 -> 0.083467859 | R17: =Q17^2 -> 0.0069668835 | T17: =2*(O17-G17)*(1-O17)*O17 -> 0.012770745 | U17: =2*(O17-G17)*(1-O17)*O17*C17 -> 0.061299578 | V17: =2*(O17-G17)*(1-O17)*O17*D17 -> 0.038312236 | W17: =2*(O17-G17)*(1-O17)*O17*E17 -> 0.017879044 | X17: =2*(O17-G17)*(1-O17)*O17*F17 -> 0.0012770745 | Y17: =IF(P17=G17,1,0) -> 1
... B84: 80 | C84: 5.5 | D84: 2.5 | E84: 4 | F84: 1.3 | G84: 1 | I84: =I83-('Konfigurasi Model'!$B$11*T83) -> 0.28099155 | J84: =J83-('Konfigurasi Model'!$B$11*U83) -> -0.27479994 | K84: =K83-('Konfigurasi Model'!$B$11*V83) -> -0.34353624 | L84: =L83-('Konfigurasi Model'!$B$11*W83) -> 1.0214763 | M84: =M83-('Konfigurasi Model'!$B$11*X83) -> 0.80103511 | N84: =I84+J84*C84+K84*D84+L84*E84+M84*F84 -> 3.0380022 | O84: =1/(1+EXP(-N84)) -> 0.95426171 | P84: =IF(O84>0.5,1,0) -> 1 | Q84: =O84-G84 -> -0.045738286 | R84: =Q84^2 -> 0.0020919908 | T84: =2*(O84-G84)*(1-O84)*O84 -> -0.0039926135 | U84: =2*(O84-G84)*(1-O84)*O84*C84 -> -0.021959374 | V84: =2*(O84-G84)*(1-O84)*O84*D84 -> -0.0099815337 | W84: =2*(O84-G84)*(1-O84)*O84*E84 -> -0.015970454 | X84: =2*(O84-G84)*(1-O84)*O84*F84 -> -0.0051903975 | Y84: =IF(P84=G84,1,0) -> 1
Q85: MSE → | R85: =AVERAGE(R5:R84) -> 0.023811702 | X85: Akurasi → | Y85: =AVERAGE(Y5:Y84) -> 0.975
A87: EPOCH 3 — TESTING (20 data, bobot = baris 84)
G88: Setosa = 0 | I88: Learning Rate | K88: ='Konfigurasi Model'!$B$11 -> 0.1
G89: Versicolor = 1 | I89: Bobot bias | N89: dot | O89: Sigmoid | P89: Prediksi | Q89: error | R89: Sum Square Error
A90: EPOCH | B90: No | C90: X1 | D90: X2 | E90: X3 | F90: X4 | G90: TARGET | I90: bias | J90: teta1 | K90: teta2 | L90: teta 3 | M90: teta4 | N90: z | O90: g(z) | T90: Akurasi
A91: testing | B91: 1 | C91: 5 | D91: 3.5 | E91: 1.3 | F91: 0.3 | G91: 0 | I91: =I84 -> 0.28099155 | J91: =J84 -> -0.27479994 | K91: =K84 -> -0.34353624 | L91: =L84 -> 1.0214763 | M91: =M84 -> 0.80103511 | N91: =I91+J91*C91+K91*D91+L91*E91+M91*F91 -> -0.72715523 | O91: =1/(1+EXP(-N91)) -> 0.3258193 | P91: =IF(O91>0.5,1,0) -> 0 | Q91: =O91-G91 -> 0.3258193 | R91: =Q91^2 -> 0.10615822 | T91: =IF(P91=G91,1,0) -> 1
B92: 2 | C92: 4.5 | D92: 2.3 | E92: 1.3 | F92: 0.3 | G92: 0 | I92: =I91 -> 0.28099155 | J92: =J91 -> -0.27479994 | K92: =K91 -> -0.34353624 | L92: =L91 -> 1.0214763 | M92: =M91 -> 0.80103511 | N92: =I92+J92*C92+K92*D92+L92*E92+M92*F92 -> -0.17751177 | O92: =1/(1+EXP(-N92)) -> 0.45573822 | P92: =IF(O92>0.5,1,0) -> 0 | Q92: =O92-G92 -> 0.45573822 | R92: =Q92^2 -> 0.20769733 | T92: =IF(P92=G92,1,0) -> 1
B93: 3 | C93: 4.4 | D93: 3.2 | E93: 1.3 | F93: 0.2 | G93: 0 | I93: =I92 -> 0.28099155 | J93: =J92 -> -0.27479994 | K93: =K92 -> -0.34353624 | L93: =L92 -> 1.0214763 | M93: =M92 -> 0.80103511 | N93: =I93+J93*C93+K93*D93+L93*E93+M93*F93 -> -0.5393179 | O93: =1/(1+EXP(-N93)) -> 0.36834627 | P93: =IF(O93>0.5,1,0) -> 0 | Q93: =O93-G93 -> 0.36834627 | R93: =Q93^2 -> 0.13567897 | T93: =IF(P93=G93,1,0) -> 1
B94: 4 | C94: 5 | D94: 3.5 | E94: 1.6 | F94: 0.6 | G94: 0 | I94: =I93 -> 0.28099155 | J94: =J93 -> -0.27479994 | K94: =K93 -> -0.34353624 | L94: =L93 -> 1.0214763 | M94: =M93 -> 0.80103511 | N94: =I94+J94*C94+K94*D94+L94*E94+M94*F94 -> -0.18040179 | O94: =1/(1+EXP(-N94)) -> 0.45502147 | P94: =IF(O94>0.5,1,0) -> 0 | Q94: =O94-G94 -> 0.45502147 | R94: =Q94^2 -> 0.20704454 | T94: =IF(P94=G94,1,0) -> 1
B95: 5 | C95: 5.1 | D95: 3.8 | E95: 1.9 | F95: 0.4 | G95: 0 | I95: =I94 -> 0.28099155 | J95: =J94 -> -0.27479994 | K95: =K94 -> -0.34353624 | L95: =L94 -> 1.0214763 | M95: =M94 -> 0.80103511 | N95: =I95+J95*C95+K95*D95+L95*E95+M95*F95 -> -0.16470678 | O95: =1/(1+EXP(-N95)) -> 0.45891614 | P95: =IF(O95>0.5,1,0) -> 0 | Q95: =O95-G95 -> 0.45891614 | R95: =Q95^2 -> 0.21060402 | T95: =IF(P95=G95,1,0) -> 1
B96: 6 | C96: 4.8 | D96: 3 | E96: 1.4 | F96: 0.3 | G96: 0 | I96: =I95 -> 0.28099155 | J96: =J95 -> -0.27479994 | K96: =K95 -> -0.34353624 | L96: =L95 -> 1.0214763 | M96: =M95 -> 0.80103511 | N96: =I96+J96*C96+K96*D96+L96*E96+M96*F96 -> -0.39827948 | O96: =1/(1+EXP(-N96)) -> 0.40172578 | P96: =IF(O96>0.5,1,0) -> 0 | Q96: =O96-G96 -> 0.40172578 | R96: =Q96^2 -> 0.1613836 | T96: =IF(P96=G96,1,0) -> 1
B97: 7 | C97: 5.1 | D97: 3.8 | E97: 1.6 | F97: 0.2 | G97: 0 | I97: =I96 -> 0.28099155 | J97: =J96 -> -0.27479994 | K97: =K96 -> -0.34353624 | L97: =L96 -> 1.0214763 | M97: =M96 -> 0.80103511 | N97: =I97+J97*C97+K97*D97+L97*E97+M97*F97 -> -0.6313567 | O97: =1/(1+EXP(-N97)) -> 0.34720297 | P97: =IF(O97>0.5,1,0) -> 0 | Q97: =O97-G97 -> 0.34720297 | R97: =Q97^2 -> 0.1205499 | T97: =IF(P97=G97,1,0) -> 1
B98: 8 | C98: 4.6 | D98: 3.2 | E98: 1.4 | F98: 0.2 | G98: 0 | I98: =I97 -> 0.28099155 | J98: =J97 -> -0.27479994 | K98: =K97 -> -0.34353624 | L98: =L97 -> 1.0214763 | M98: =M97 -> 0.80103511 | N98: =I98+J98*C98+K98*D98+L98*E98+M98*F98 -> -0.49213026 | O98: =1/(1+EXP(-N98)) -> 0.37939186 | P98: =IF(O98>0.5,1,0) -> 0 | Q98: =O98-G98 -> 0.37939186 | R98: =Q98^2 -> 0.14393819 | T98: =IF(P98=G98,1,0) -> 1
B99: 9 | C99: 5.3 | D99: 3.7 | E99: 1.5 | F99: 0.2 | G99: 0 | I99: =I98 -> 0.28099155 | J99: =J98 -> -0.27479994 | K99: =K98 -> -0.34353624 | L99: =L98 -> 1.0214763 | M99: =M98 -> 0.80103511 | N99: =I99+J99*C99+K99*D99+L99*E99+M99*F99 -> -0.7541107 | O99: =1/(1+EXP(-N99)) -> 0.31992626 | P99: =IF(O99>0.5,1,0) -> 0 | Q99: =O99-G99 -> 0.31992626 | R99: =Q99^2 -> 0.10235281 | T99: =IF(P99=G99,1,0) -> 1
B100: 10 | C100: 5 | D100: 3.3 | E100: 1.4 | F100: 0.2 | G100: 0 | I100: =I99 -> 0.28099155 | J100: =J99 -> -0.27479994 | K100: =K99 -> -0.34353624 | L100: =L99 -> 1.0214763 | M100: =M99 -> 0.80103511 | N100: =I100+J100*C100+K100*D100+L100*E100+M100*F100 -> -0.63640385 | O100: =1/(1+EXP(-N100)) -> 0.3460599 | P100: =IF(O100>0.5,1,0) -> 0 | Q100: =O100-G100 -> 0.3460599 | R100: =Q100^2 -> 0.11975746 | T100: =IF(P100=G100,1,0) -> 1
B101: 11 | C101: 5.5 | D101: 2.6 | E101: 4.4 | F101: 1.2 | G101: 1 | I101: =I100 -> 0.28099155 | J101: =J100 -> -0.27479994 | K101: =K100 -> -0.34353624 | L101: =L100 -> 1.0214763 | M101: =M100 -> 0.80103511 | N101: =I101+J101*C101+K101*D101+L101*E101+M101*F101 -> 3.3321356 | O101: =1/(1+EXP(-N101)) -> 0.96551495 | P101: =IF(O101>0.5,1,0) -> 1 | Q101: =O101-G101 -> -0.034485051 | R101: =Q101^2 -> 0.0011892188 | T101: =IF(P101=G101,1,0) -> 1
B102: 12 | C102: 6.1 | D102: 3 | E102: 4.6 | F102: 1.4 | G102: 1 | I102: =I101 -> 0.28099155 | J102: =J101 -> -0.27479994 | K102: =K101 -> -0.34353624 | L102: =L101 -> 1.0214763 | M102: =M101 -> 0.80103511 | N102: =I102+J102*C102+K102*D102+L102*E102+M102*F102 -> 3.3943435 | O102: =1/(1+EXP(-N102)) -> 0.96752729 | P102: =IF(O102>0.5,1,0) -> 1 | Q102: =O102-G102 -> -0.032472714 | R102: =Q102^2 -> 0.0010544771 | T102: =IF(P102=G102,1,0) -> 1
B103: 13 | C103: 5.8 | D103: 2.6 | E103: 4 | F103: 1.2 | G103: 1 | I103: =I102 -> 0.28099155 | J103: =J102 -> -0.27479994 | K103: =K102 -> -0.34353624 | L103: =L102 -> 1.0214763 | M103: =M102 -> 0.80103511 | N103: =I103+J103*C103+K103*D103+L103*E103+M103*F103 -> 2.8411051 | O103: =1/(1+EXP(-N103)) -> 0.94485707 | P103: =IF(O103>0.5,1,0) -> 1 | Q103: =O103-G103 -> -0.05514293 | R103: =Q103^2 -> 0.0030407427 | T103: =IF(P103=G103,1,0) -> 1
... B110: 20 | C110: 5.7 | D110: 2.8 | E110: 4.1 | F110: 1.3 | G110: 1 | I110: =I109 -> 0.28099155 | J110: =J109 -> -0.27479994 | K110: =K109 -> -0.34353624 | L110: =L109 -> 1.0214763 | M110: =M109 -> 0.80103511 | N110: =I110+J110*C110+K110*D110+L110*E110+M110*F110 -> 2.982129 | O110: =1/(1+EXP(-N110)) -> 0.95176021 | P110: =IF(O110>0.5,1,0) -> 1 | Q110: =O110-G110 -> -0.048239785 | R110: =Q110^2 -> 0.0023270769 | T110: =IF(P110=G110,1,0) -> 1
Q111: MSE → | R111: =AVERAGE(R91:R110) -> 0.077740282 | T111: =AVERAGE(T91:T110) -> 1
A113: Confusion Matrix (data testing) | I113: Evaluation Metrics
C114: Prediksi | I114: Metrik | J114: Hasil (%)
...

Sheet Epoch 4
A1: EPOCH 4 — TRAINING (80 data)
G2: Setosa = 0 | I2: Learning Rate | K2: ='Konfigurasi Model'!$B$11 -> 0.1
G3: Versicolor = 1 | I3: Bobot bias | N3: dot | O3: Sigmoid | P3: Prediksi | Q3: error | R3: Sum Square Error
A4: EPOCH | B4: No | C4: X1 | D4: X2 | E4: X3 | F4: X4 | G4: TARGET | I4: bias | J4: teta1 | K4: teta2 | L4: teta 3 | M4: teta4 | N4: z | O4: g(z) | T4: dbias | U4: dteta1 | V4: dteta2 | W4: dteta3 | X4: dteta4 | Y4: Akurasi
A5: epoch 4 | B5: 1 | C5: 5.1 | D5: 3.5 | E5: 1.4 | F5: 0.2 | G5: 0 | I5: ='Epoch 3'!I84 -> 0.28099155 | J5: ='Epoch 3'!J84 -> -0.27479994 | K5: ='Epoch 3'!K84 -> -0.34353624 | L5: ='Epoch 3'!L84 -> 1.0214763 | M5: ='Epoch 3'!M84 -> 0.80103511 | N5: =I5+J5*C5+K5*D5+L5*E5+M5*F5 -> -0.7325911 | O5: =1/(1+EXP(-N5)) -> 0.32462639 | P5: =IF(O5>0.5,1,0) -> 0 | Q5: =O5-G5 -> 0.32462639 | R5: =Q5^2 -> 0.10538229 | T5: =2*(O5-G5)*(1-O5)*O5 -> 0.14234484 | U5: =2*(O5-G5)*(1-O5)*O5*C5 -> 0.72595867 | V5: =2*(O5-G5)*(1-O5)*O5*D5 -> 0.49820693 | W5: =2*(O5-G5)*(1-O5)*O5*E5 -> 0.19928277 | X5: =2*(O5-G5)*(1-O5)*O5*F5 -> 0.028468967 | Y5: =IF(P5=G5,1,0) -> 1
B6: 2 | C6: 4.9 | D6: 3 | E6: 1.4 | F6: 0.2 | G6: 0 | I6: =I5-('Konfigurasi Model'!$B$11*T5) -> 0.26675706 | J6: =J5-('Konfigurasi Model'!$B$11*U5) -> -0.3473958 | K6: =K5-('Konfigurasi Model'!$B$11*V5) -> -0.39335694 | L6: =L5-('Konfigurasi Model'!$B$11*W5) -> 1.0015481 | M6: =M5-('Konfigurasi Model'!$B$11*X5) -> 0.79818821 | N6: =I6+J6*C6+K6*D6+L6*E6+M6*F6 -> -1.0537483 | O6: =1/(1+EXP(-N6)) -> 0.25850598 | P6: =IF(O6>0.5,1,0) -> 0 | Q6: =O6-G6 -> 0.25850598 | R6: =Q6^2 -> 0.066825342 | T6: =2*(O6-G6)*(1-O6)*O6 -> 0.099101183 | U6: =2*(O6-G6)*(1-O6)*O6*C6 -> 0.4855958 | V6: =2*(O6-G6)*(1-O6)*O6*D6 -> 0.29730355 | W6: =2*(O6-G6)*(1-O6)*O6*E6 -> 0.13874166 | X6: =2*(O6-G6)*(1-O6)*O6*F6 -> 0.019820237 | Y6: =IF(P6=G6,1,0) -> 1
B7: 3 | C7: 4.7 | D7: 3.2 | E7: 1.3 | F7: 0.2 | G7: 0 | I7: =I6-('Konfigurasi Model'!$B$11*T6) -> 0.25684694 | J7: =J6-('Konfigurasi Model'!$B$11*U6) -> -0.39595538 | K7: =K6-('Konfigurasi Model'!$B$11*V6) -> -0.42308729 | L7: =L6-('Konfigurasi Model'!$B$11*W6) -> 0.98767389 | M7: =M6-('Konfigurasi Model'!$B$11*X6) -> 0.79620619 | N7: =I7+J7*C7+K7*D7+L7*E7+M7*F7 -> -1.5148054 | O7: =1/(1+EXP(-N7)) -> 0.18022773 | P7: =IF(O7>0.5,1,0) -> 0 | Q7: =O7-G7 -> 0.18022773 | R7: =Q7^2 -> 0.032482033 | T7: =2*(O7-G7)*(1-O7)*O7 -> 0.05325574 | U7: =2*(O7-G7)*(1-O7)*O7*C7 -> 0.25030198 | V7: =2*(O7-G7)*(1-O7)*O7*D7 -> 0.17041837 | W7: =2*(O7-G7)*(1-O7)*O7*E7 -> 0.069232462 | X7: =2*(O7-G7)*(1-O7)*O7*F7 -> 0.010651148 | Y7: =IF(P7=G7,1,0) -> 1
B8: 4 | C8: 4.6 | D8: 3.1 | E8: 1.5 | F8: 0.2 | G8: 0 | I8: =I7-('Konfigurasi Model'!$B$11*T7) -> 0.25152137 | J8: =J7-('Konfigurasi Model'!$B$11*U7) -> -0.42098558 | K8: =K7-('Konfigurasi Model'!$B$11*V7) -> -0.44012913 | L8: =L7-('Konfigurasi Model'!$B$11*W7) -> 0.98075064 | M8: =M7-('Konfigurasi Model'!$B$11*X7) -> 0.79514107 | N8: =I8+J8*C8+K8*D8+L8*E8+M8*F8 -> -1.4192584 | O8: =1/(1+EXP(-N8)) -> 0.19477787 | P8: =IF(O8>0.5,1,0) -> 0 | Q8: =O8-G8 -> 0.19477787 | R8: =Q8^2 -> 0.037938417 | T8: =2*(O8-G8)*(1-O8)*O8 -> 0.061097706 | U8: =2*(O8-G8)*(1-O8)*O8*C8 -> 0.28104945 | V8: =2*(O8-G8)*(1-O8)*O8*D8 -> 0.18940289 | W8: =2*(O8-G8)*(1-O8)*O8*E8 -> 0.091646559 | X8: =2*(O8-G8)*(1-O8)*O8*F8 -> 0.012219541 | Y8: =IF(P8=G8,1,0) -> 1
B9: 5 | C9: 5 | D9: 3.6 | E9: 1.4 | F9: 0.2 | G9: 0 | I9: =I8-('Konfigurasi Model'!$B$11*T8) -> 0.2454116 | J9: =J8-('Konfigurasi Model'!$B$11*U8) -> -0.44909053 | K9: =K8-('Konfigurasi Model'!$B$11*V8) -> -0.45906942 | L9: =L8-('Konfigurasi Model'!$B$11*W8) -> 0.97158599 | M9: =M8-('Konfigurasi Model'!$B$11*X8) -> 0.79391912 | N9: =I9+J9*C9+K9*D9+L9*E9+M9*F9 -> -2.1336867 | O9: =1/(1+EXP(-N9)) -> 0.10586551 | P9: =IF(O9>0.5,1,0) -> 0 | Q9: =O9-G9 -> 0.10586551 | R9: =Q9^2 -> 0.011207505 | T9: =2*(O9-G9)*(1-O9)*O9 -> 0.020042034 | U9: =2*(O9-G9)*(1-O9)*O9*C9 -> 0.10021017 | V9: =2*(O9-G9)*(1-O9)*O9*D9 -> 0.072151323 | W9: =2*(O9-G9)*(1-O9)*O9*E9 -> 0.028058848 | X9: =2*(O9-G9)*(1-O9)*O9*F9 -> 0.0040084069 | Y9: =IF(P9=G9,1,0) -> 1
